Workbook

Sheet Input
B1: Inferno | C1: Aqua | D1: Flora | E1: Terra | F1: Wind | G1: Lightning | H1: Frost | I1: Mind | J1: Spirit | K1: Cursed | L1: Bless | M1: Mythos | N1: Cyber | O1: Cosmic | P1: Neutral | S1: Inferno | T1: Aqua | U1: Flora | V1: Terra | W1: Wind | X1: Lightning | Y1: Frost | Z1: Mind | AA1: Spirit | AB1: Cursed | AC1: Bless | AD1: Mythos | AE1: Cyber | AF1: Cosmic | AG1: Neutral
A2: Inferno | B2: 0.5 | C2: 0.5 | D2: 2 | E2: 2 | F2: 0.5 | G2: 1 | H2: 2 | I2: 1 | J2: 0.5 | K2: 1 | L2: 2 | M2: 1 | N2: 2 | O2: 1 | P2: 1 | R2: Inferno | S2: {=_xlfn.IFS(B2=1,1,B2=2,2,B2=0.5,0,B2=0,-1)} -> 0 | T2: {=_xlfn.IFS(C2=1,1,C2=2,2,C2=0.5,0,C2=0,-1)} -> 0 | U2: {=_xlfn.IFS(D2=1,1,D2=2,2,D2=0.5,0,D2=0,-1)} -> 2 | V2: {=_xlfn.IFS(E2=1,1,E2=2,2,E2=0.5,0,E2=0,-1)} -> 2 | W2: {=_xlfn.IFS(F2=1,1,F2=2,2,F2=0.5,0,F2=0,-1)} -> 0 | X2: {=_xlfn.IFS(G2=1,1,G2=2,2,G2=0.5,0,G2=0,-1)} -> 1 | Y2: {=_xlfn.IFS(H2=1,1,H2=2,2,H2=0.5,0,H2=0,-1)} -> 2 | Z2: {=_xlfn.IFS(I2=1,1,I2=2,2,I2=0.5,0,I2=0,-1)} -> 1 | ... AG2: {=_xlfn.IFS(P2=1,1,P2=2,2,P2=0.5,0,P2=0,-1)} -> 1 | AH2: =SUM(S2:AG2) -> 16
A3: Aqua | B3: 2 | C3: 0.5 | D3: 0.5 | E3: 2 | F3: 1 | G3: 1 | H3: 0.5 | I3: 1 | J3: 0.5 | K3: 1 | L3: 1 | M3: 1 | N3: 2 | O3: 0.5 | P3: 1 | R3: Aqua | S3: {=_xlfn.IFS(B3=1,1,B3=2,2,B3=0.5,0,B3=0,-1)} -> 2 | T3: {=_xlfn.IFS(C3=1,1,C3=2,2,C3=0.5,0,C3=0,-1)} -> 0 | U3: {=_xlfn.IFS(D3=1,1,D3=2,2,D3=0.5,0,D3=0,-1)} -> 0 | V3: {=_xlfn.IFS(E3=1,1,E3=2,2,E3=0.5,0,E3=0,-1)} -> 2 | W3: {=_xlfn.IFS(F3=1,1,F3=2,2,F3=0.5,0,F3=0,-1)} -> 1 | X3: {=_xlfn.IFS(G3=1,1,G3=2,2,G3=0.5,0,G3=0,-1)} -> 1 | Y3: {=_xlfn.IFS(H3=1,1,H3=2,2,H3=0.5,0,H3=0,-1)} -> 0 | Z3: {=_xlfn.IFS(I3=1,1,I3=2,2,I3=0.5,0,I3=0,-1)} -> 1 | ... AG3: {=_xlfn.IFS(P3=1,1,P3=2,2,P3=0.5,0,P3=0,-1)} -> 1 | AH3: =SUM(S3:AG3) -> 13
A4: Flora | B4: 0.5 | C4: 2 | D4: 0.5 | E4: 2 | F4: 0.5 | G4: 1 | H4: 0.5 | I4: 1 | J4: 1 | K4: 1 | L4: 0.5 | M4: 1 | N4: 2 | O4: 1 | P4: 1 | R4: Flora | S4: {=_xlfn.IFS(B4=1,1,B4=2,2,B4=0.5,0,B4=0,-1)} -> 0 | T4: {=_xlfn.IFS(C4=1,1,C4=2,2,C4=0.5,0,C4=0,-1)} -> 2 | U4: {=_xlfn.IFS(D4=1,1,D4=2,2,D4=0.5,0,D4=0,-1)} -> 0 | V4: {=_xlfn.IFS(E4=1,1,E4=2,2,E4=0.5,0,E4=0,-1)} -> 2 | W4: {=_xlfn.IFS(F4=1,1,F4=2,2,F4=0.5,0,F4=0,-1)} -> 0 | X4: {=_xlfn.IFS(G4=1,1,G4=2,2,G4=0.5,0,G4=0,-1)} -> 1 | Y4: {=_xlfn.IFS(H4=1,1,H4=2,2,H4=0.5,0,H4=0,-1)} -> 0 | Z4: {=_xlfn.IFS(I4=1,1,I4=2,2,I4=0.5,0,I4=0,-1)} -> 1 | ... AG4: {=_xlfn.IFS(P4=1,1,P4=2,2,P4=0.5,0,P4=0,-1)} -> 1 | AH4: =SUM(S4:AG4) -> 13
A5: Terra | B5: 2 | C5: 1 | D5: 0.5 | E5: 0.5 | F5: 0 | G5: 2 | H5: 0.5 | I5: 0.5 | J5: 0.5 | K5: 1 | L5: 1 | M5: 1 | N5: 1 | O5: 1 | P5: 1 | R5: Terra | S5: {=_xlfn.IFS(B5=1,1,B5=2,2,B5=0.5,0,B5=0,-1)} -> 2 | T5: {=_xlfn.IFS(C5=1,1,C5=2,2,C5=0.5,0,C5=0,-1)} -> 1 | U5: {=_xlfn.IFS(D5=1,1,D5=2,2,D5=0.5,0,D5=0,-1)} -> 0 | V5: {=_xlfn.IFS(E5=1,1,E5=2,2,E5=0.5,0,E5=0,-1)} -> 0 | W5: {=_xlfn.IFS(F5=1,1,F5=2,2,F5=0.5,0,F5=0,-1)} -> -1 | X5: {=_xlfn.IFS(G5=1,1,G5=2,2,G5=0.5,0,G5=0,-1)} -> 2 | Y5: {=_xlfn.IFS(H5=1,1,H5=2,2,H5=0.5,0,H5=0,-1)} -> 0 | Z5: {=_xlfn.IFS(I5=1,1,I5=2,2,I5=0.5,0,I5=0,-1)} -> 0 | ... AG5: {=_xlfn.IFS(P5=1,1,P5=2,2,P5=0.5,0,P5=0,-1)} -> 1 | AH5: =SUM(S5:AG5) -> 10
A6: Wind | B6: 2 | C6: 1 | D6: 1 | E6: 0 | F6: 0.5 | G6: 1 | H6: 2 | I6: 1 | J6: 2 | K6: 1 | L6: 2 | M6: 1 | N6: 0.5 | O6: 1 | P6: 1 | R6: Wind | S6: {=_xlfn.IFS(B6=1,1,B6=2,2,B6=0.5,0,B6=0,-1)} -> 2 | T6: {=_xlfn.IFS(C6=1,1,C6=2,2,C6=0.5,0,C6=0,-1)} -> 1 | U6: {=_xlfn.IFS(D6=1,1,D6=2,2,D6=0.5,0,D6=0,-1)} -> 1 | V6: {=_xlfn.IFS(E6=1,1,E6=2,2,E6=0.5,0,E6=0,-1)} -> -1 | W6: {=_xlfn.IFS(F6=1,1,F6=2,2,F6=0.5,0,F6=0,-1)} -> 0 | X6: {=_xlfn.IFS(G6=1,1,G6=2,2,G6=0.5,0,G6=0,-1)} -> 1 | Y6: {=_xlfn.IFS(H6=1,1,H6=2,2,H6=0.5,0,H6=0,-1)} -> 2 | Z6: {=_xlfn.IFS(I6=1,1,I6=2,2,I6=0.5,0,I6=0,-1)} -> 1 | ... AG6: {=_xlfn.IFS(P6=1,1,P6=2,2,P6=0.5,0,P6=0,-1)} -> 1 | AH6: =SUM(S6:AG6) -> 15
A7: Lightning | B7: 1 | C7: 2 | D7: 1 | E7: 0 | F7: 2 | G7: 0.5 | H7: 0.5 | I7: 0.5 | J7: 2 | K7: 1 | L7: 2 | M7: 1 | N7: 2 | O7: 0.5 | P7: 1 | R7: Lightning | S7: {=_xlfn.IFS(B7=1,1,B7=2,2,B7=0.5,0,B7=0,-1)} -> 1 | T7: {=_xlfn.IFS(C7=1,1,C7=2,2,C7=0.5,0,C7=0,-1)} -> 2 | U7: {=_xlfn.IFS(D7=1,1,D7=2,2,D7=0.5,0,D7=0,-1)} -> 1 | V7: {=_xlfn.IFS(E7=1,1,E7=2,2,E7=0.5,0,E7=0,-1)} -> -1 | W7: {=_xlfn.IFS(F7=1,1,F7=2,2,F7=0.5,0,F7=0,-1)} -> 2 | X7: {=_xlfn.IFS(G7=1,1,G7=2,2,G7=0.5,0,G7=0,-1)} -> 0 | Y7: {=_xlfn.IFS(H7=1,1,H7=2,2,H7=0.5,0,H7=0,-1)} -> 0 | Z7: {=_xlfn.IFS(I7=1,1,I7=2,2,I7=0.5,0,I7=0,-1)} -> 0 | ... AG7: {=_xlfn.IFS(P7=1,1,P7=2,2,P7=0.5,0,P7=0,-1)} -> 1 | AH7: =SUM(S7:AG7) -> 14
A8: Frost | B8: 0.5 | C8: 0.5 | D8: 2 | E8: 0.5 | F8: 2 | G8: 0.5 | H8: 0.5 | I8: 1 | J8: 1 | K8: 1 | L8: 0.5 | M8: 0.5 | N8: 2 | O8: 0.5 | P8: 1 | R8: Frost | S8: {=_xlfn.IFS(B8=1,1,B8=2,2,B8=0.5,0,B8=0,-1)} -> 0 | T8: {=_xlfn.IFS(C8=1,1,C8=2,2,C8=0.5,0,C8=0,-1)} -> 0 | U8: {=_xlfn.IFS(D8=1,1,D8=2,2,D8=0.5,0,D8=0,-1)} -> 2 | V8: {=_xlfn.IFS(E8=1,1,E8=2,2,E8=0.5,0,E8=0,-1)} -> 0 | W8: {=_xlfn.IFS(F8=1,1,F8=2,2,F8=0.5,0,F8=0,-1)} -> 2 | X8: {=_xlfn.IFS(G8=1,1,G8=2,2,G8=0.5,0,G8=0,-1)} -> 0 | Y8: {=_xlfn.IFS(H8=1,1,H8=2,2,H8=0.5,0,H8=0,-1)} -> 0 | Z8: {=_xlfn.IFS(I8=1,1,I8=2,2,I8=0.5,0,I8=0,-1)} -> 1 | ... AG8: {=_xlfn.IFS(P8=1,1,P8=2,2,P8=0.5,0,P8=0,-1)} -> 1 | AH8: =SUM(S8:AG8) -> 10
A9: Mind | B9: 2 | C9: 1 | D9: 1 | E9: 0.5 | F9: 2 | G9: 2 | H9: 1 | I9: 1 | J9: 0 | K9: 0.5 | L9: 2 | M9: 1 | N9: 0.5 | O9: 1 | P9: 1 | R9: Mind | S9: {=_xlfn.IFS(B9=1,1,B9=2,2,B9=0.5,0,B9=0,-1)} -> 2 | T9: {=_xlfn.IFS(C9=1,1,C9=2,2,C9=0.5,0,C9=0,-1)} -> 1 | U9: {=_xlfn.IFS(D9=1,1,D9=2,2,D9=0.5,0,D9=0,-1)} -> 1 | V9: {=_xlfn.IFS(E9=1,1,E9=2,2,E9=0.5,0,E9=0,-1)} -> 0 | W9: {=_xlfn.IFS(F9=1,1,F9=2,2,F9=0.5,0,F9=0,-1)} -> 2 | X9: {=_xlfn.IFS(G9=1,1,G9=2,2,G9=0.5,0,G9=0,-1)} -> 2 | Y9: {=_xlfn.IFS(H9=1,1,H9=2,2,H9=0.5,0,H9=0,-1)} -> 1 | Z9: {=_xlfn.IFS(I9=1,1,I9=2,2,I9=0.5,0,I9=0,-1)} -> 1 | ... AG9: {=_xlfn.IFS(P9=1,1,P9=2,2,P9=0.5,0,P9=0,-1)} -> 1 | AH9: =SUM(S9:AG9) -> 14
A10: Spirit | B10: 1 | C10: 1 | D10: 0.5 | E10: 0.5 | F10: 1 | G10: 0.5 | H10: 1 | I10: 2 | J10: 1 | K10: 0 | L10: 0.5 | M10: 1 | N10: 1 | O10: 2 | P10: 1 | R10: Spirit | S10: {=_xlfn.IFS(B10=1,1,B10=2,2,B10=0.5,0,B10=0,-1)} -> 1 | T10: {=_xlfn.IFS(C10=1,1,C10=2,2,C10=0.5,0,C10=0,-1)} -> 1 | U10: {=_xlfn.IFS(D10=1,1,D10=2,2,D10=0.5,0,D10=0,-1)} -> 0 | V10: {=_xlfn.IFS(E10=1,1,E10=2,2,E10=0.5,0,E10=0,-1)} -> 0 | W10: {=_xlfn.IFS(F10=1,1,F10=2,2,F10=0.5,0,F10=0,-1)} -> 1 | X10: {=_xlfn.IFS(G10=1,1,G10=2,2,G10=0.5,0,G10=0,-1)} -> 0 | Y10: {=_xlfn.IFS(H10=1,1,H10=2,2,H10=0.5,0,H10=0,-1)} -> 1 | Z10: {=_xlfn.IFS(I10=1,1,I10=2,2,I10=0.5,0,I10=0,-1)} -> 2 | ... AG10: {=_xlfn.IFS(P10=1,1,P10=2,2,P10=0.5,0,P10=0,-1)} -> 1 | AH10: =SUM(S10:AG10) -> 11
A11: Cursed | B11: 0.5 | C11: 1 | D11: 1 | E11: 0.5 | F11: 1 | G11: 2 | H11: 1 | I11: 0.5 | J11: 2 | K11: 1 | L11: 0 | M11: 1 | N11: 2 | O11: 1 | P11: 1 | R11: Cursed | S11: {=_xlfn.IFS(B11=1,1,B11=2,2,B11=0.5,0,B11=0,-1)} -> 0 | T11: {=_xlfn.IFS(C11=1,1,C11=2,2,C11=0.5,0,C11=0,-1)} -> 1 | U11: {=_xlfn.IFS(D11=1,1,D11=2,2,D11=0.5,0,D11=0,-1)} -> 1 | V11: {=_xlfn.IFS(E11=1,1,E11=2,2,E11=0.5,0,E11=0,-1)} -> 0 | W11: {=_xlfn.IFS(F11=1,1,F11=2,2,F11=0.5,0,F11=0,-1)} -> 1 | X11: {=_xlfn.IFS(G11=1,1,G11=2,2,G11=0.5,0,G11=0,-1)} -> 2 | Y11: {=_xlfn.IFS(H11=1,1,H11=2,2,H11=0.5,0,H11=0,-1)} -> 1 | Z11: {=_xlfn.IFS(I11=1,1,I11=2,2,I11=0.5,0,I11=0,-1)} -> 0 | ... AG11: {=_xlfn.IFS(P11=1,1,P11=2,2,P11=0.5,0,P11=0,-1)} -> 1 | AH11: =SUM(S11:AG11) -> 13
A12: Bless | B12: 2 | C12: 1 | D12: 1 | E12: 1 | F12: 2 | G12: 0.5 | H12: 0.5 | I12: 0 | J12: 0.5 | K12: 2 | L12: 1 | M12: 1 | N12: 1 | O12: 0.5 | P12: 1 | R12: Bless | S12: {=_xlfn.IFS(B12=1,1,B12=2,2,B12=0.5,0,B12=0,-1)} -> 2 | T12: {=_xlfn.IFS(C12=1,1,C12=2,2,C12=0.5,0,C12=0,-1)} -> 1 | U12: {=_xlfn.IFS(D12=1,1,D12=2,2,D12=0.5,0,D12=0,-1)} -> 1 | V12: {=_xlfn.IFS(E12=1,1,E12=2,2,E12=0.5,0,E12=0,-1)} -> 1 | W12: {=_xlfn.IFS(F12=1,1,F12=2,2,F12=0.5,0,F12=0,-1)} -> 2 | X12: {=_xlfn.IFS(G12=1,1,G12=2,2,G12=0.5,0,G12=0,-1)} -> 0 | Y12: {=_xlfn.IFS(H12=1,1,H12=2,2,H12=0.5,0,H12=0,-1)} -> 0 | Z12: {=_xlfn.IFS(I12=1,1,I12=2,2,I12=0.5,0,I12=0,-1)} -> -1 | ... AG12: {=_xlfn.IFS(P12=1,1,P12=2,2,P12=0.5,0,P12=0,-1)} -> 1 | AH12: =SUM(S12:AG12) -> 12
A13: Mythos | B13: 1 | C13: 1 | D13: 1 | E13: 1 | F13: 2 | G13: 1 | H13: 1 | I13: 2 | J13: 1 | K13: 1 | L13: 0.5 | M13: 0.5 | N13: 0 | O13: 0.5 | P13: 1 | R13: Mythos | S13: {=_xlfn.IFS(B13=1,1,B13=2,2,B13=0.5,0,B13=0,-1)} -> 1 | T13: {=_xlfn.IFS(C13=1,1,C13=2,2,C13=0.5,0,C13=0,-1)} -> 1 | U13: {=_xlfn.IFS(D13=1,1,D13=2,2,D13=0.5,0,D13=0,-1)} -> 1 | V13: {=_xlfn.IFS(E13=1,1,E13=2,2,E13=0.5,0,E13=0,-1)} -> 1 | W13: {=_xlfn.IFS(F13=1,1,F13=2,2,F13=0.5,0,F13=0,-1)} -> 2 | X13: {=_xlfn.IFS(G13=1,1,G13=2,2,G13=0.5,0,G13=0,-1)} -> 1 | Y13: {=_xlfn.IFS(H13=1,1,H13=2,2,H13=0.5,0,H13=0,-1)} -> 1 | Z13: {=_xlfn.IFS(I13=1,1,I13=2,2,I13=0.5,0,I13=0,-1)} -> 2 | ... AG13: {=_xlfn.IFS(P13=1,1,P13=2,2,P13=0.5,0,P13=0,-1)} -> 1 | AH13: =SUM(S13:AG13) -> 12
... A16: Neutral | B16: 1 | C16: 1 | D16: 1 | E16: 1 | F16: 1 | G16: 1 | H16: 1 | I16: 1 | J16: 1 | K16: 1 | L16: 1 | M16: 1 | N16: 1 | O16: 1 | P16: 1 | R16: Neutral | S16: {=_xlfn.IFS(B16=1,1,B16=2,2,B16=0.5,0,B16=0,-1)} -> 1 | T16: {=_xlfn.IFS(C16=1,1,C16=2,2,C16=0.5,0,C16=0,-1)} -> 1 | U16: {=_xlfn.IFS(D16=1,1,D16=2,2,D16=0.5,0,D16=0,-1)} -> 1 | V16: {=_xlfn.IFS(E16=1,1,E16=2,2,E16=0.5,0,E16=0,-1)} -> 1 | W16: {=_xlfn.IFS(F16=1,1,F16=2,2,F16=0.5,0,F16=0,-1)} -> 1 | X16: {=_xlfn.IFS(G16=1,1,G16=2,2,G16=0.5,0,G16=0,-1)} -> 1 | Y16: {=_xlfn.IFS(H16=1,1,H16=2,2,H16=0.5,0,H16=0,-1)} -> 1 | Z16: {=_xlfn.IFS(I16=1,1,I16=2,2,I16=0.5,0,I16=0,-1)} -> 1 | ... AG16: {=_xlfn.IFS(P16=1,1,P16=2,2,P16=0.5,0,P16=0,-1)} -> 1 | AH16: =SUM(S16:AG16) -> 15
S17: =SUM(S2:S16) -> 16 | T17: =SUM(T2:T16) -> 13 | U17: =SUM(U2:U16) -> 13 | V17: =SUM(V2:V16) -> 9 | W17: =SUM(W2:W16) -> 16 | X17: =SUM(X2:X16) -> 14 | Y17: =SUM(Y2:Y16) -> 10 | Z17: =SUM(Z2:Z16) -> 14 | ... AH17: =SUM(AH2:AH16) -> 194
A19: Things Outside of Type Match Up that Gives Advantages | S19: Attack | T19: Defense | U19: Diff
R20: Inferno | S20: =AH2 -> 16 | T20: =S17 -> 16 | U20: =S20-T20 -> 0 | W20: 15 | X20: 16 | Y20: =OR(S20=X20,S20=W20) -> TRUE | Z20: =U20=0 -> TRUE | AA20: =AND(Z20,Y20) -> TRUE
A21: Type distribution in available pool of playable champions | R21: Aqua | S21: =AH3 -> 13 | T21: =T17 -> 13 | U21: =S21-T21 -> 0 | W21: 13 | X21: 14 | Y21: =OR(S21=X21,S21=W21) -> TRUE | Z21: =U21=0 -> TRUE | AA21: =AND(Z21,Y21) -> TRUE
A22: Move pool depth and quality (strength, secondary affects) | R22: Flora | S22: =AH4 -> 13 | T22: =U17 -> 13 | U22: =S22-T22 -> 0 | W22: 12 | X22: 13 | Y22: =OR(S22=X22,S22=W22) -> TRUE | Z22: =U22=0 -> TRUE | AA22: =AND(Z22,Y22) -> TRUE
A23: Average stat distribution by essence | I23: Triangles / Dualities | R23: Terra | S23: =AH5 -> 10 | T23: =V17 -> 9 | U23: =S23-T23 -> 1 | V23: <<- devasion | W23: 9 | X23: 10 | Y23: =OR(S23=X23,S23=W23) -> TRUE | Z23: =U23=1 -> TRUE | AA23: =AND(Z23,Y23) -> TRUE
A24: Essence specific perks | I24: Fire-Water-Grass | R24: Wind | S24: =AH6 -> 15 | T24: =W17 -> 16 | U24: =S24-T24 -> -1 | V24: <<- evasion | W24: 14 | X24: 15 | Y24: =OR(S24=X24,S24=W24) -> TRUE | Z24: =U24=-1 -> TRUE | AA24: =AND(Z24,Y24) -> TRUE
A25: Immunities --> Potentially 3x beneficial than neutral | I25: Fly-Ground | R25: Lightning | S25: =AH7 -> 14 | T25: =X17 -> 14 | U25: =S25-T25 -> 0 | W25: 14 | X25: 15 | Y25: =OR(S25=X25,S25=W25) -> TRUE | Z25: =U25=0 -> TRUE | AA25: =AND(Z25,Y25) -> TRUE
A26: Flexibility in dual typing | I26: Ice-Lighting | R26: Frost | S26: =AH8 -> 10 | T26: =Y17 -> 10 | U26: =S26-T26 -> 0 | W26: 9 | X26: 10 | Y26: =OR(S26=X26,S26=W26) -> TRUE | Z26: =U26=0 -> TRUE | AA26: =AND(Z26,Y26) -> TRUE
A27: Typing and role alignment | I27: Mind-Spirit-Cursed-Bless | R27: Mind | S27: =AH9 -> 14 | T27: =Z17 -> 14 | U27: =S27-T27 -> 0 | W27: 13 | X27: 14 | Y27: =OR(S27=X27,S27=W27) -> TRUE | Z27: =U27=0 -> TRUE | AA27: =AND(Z27,Y27) -> TRUE
I28: Mthos-Cyber-Cosmic | R28: Spirit | S28: =AH10 -> 11 | T28: =AA17 -> 11 | U28: =S28-T28 -> 0 | W28: 10 | X28: 11 | Y28: =OR(S28=X28,S28=W28) -> TRUE | Z28: =U28=0 -> TRUE | AA28: =AND(Z28,Y28) -> TRUE
A29: Mythos & Cosmic = Higher Base Stats, worse matchups | I29: Neutral | R29: Cursed | S29: =AH11 -> 13 | T29: =AB17 -> 13 | U29: =S29-T29 -> 0 | W29: 13 | X29: 14 | Y29: =OR(S29=X29,S29=W29) -> TRUE | Z29: =U29=0 -> TRUE | AA29: =AND(Z29,Y29) -> TRUE
A30: Cyber = Better matchups, Lower base stats | R30: Bless | S30: =AH12 -> 12 | T30: =AC17 -> 12 | U30: =S30-T30 -> 0 | W30: 11 | X30: 12 | Y30: =OR(S30=X30,S30=W30) -> TRUE | Z30: =U30=0 -> TRUE | AA30: =AND(Z30,Y30) -> TRUE
A31: Wind = Less resistances, offset with evasion | R31: Mythos | S31: =AH13 -> 12 | T31: =AD17 -> 13 | U31: =S31-T31 -> -1 | V31: << better base stats | W31: 12 | X31: 12 | Y31: =OR(S31=X31,S31=W31) -> TRUE | Z31: =U31=-1 -> TRUE | AA31: =AND(Z31,Y31) -> TRUE
A32: Ground = More resistances, offset with devasion | R32: Cyber | S32: =AH14 -> 14 | T32: =AE17 -> 14 | U32: =S32-T32 -> 0 | W32: 14 | X32: 14 | Y32: =OR(S32=X32,S32=W32) -> TRUE | Z32: =U32=0 -> TRUE | AA32: =AND(Z32,Y32) -> TRUE
R33: Cosmic | S33: =AH15 -> 12 | T33: =AF17 -> 11 | U33: =S33-T33 -> 1 | V33: << worse base stats | W33: 12 | X33: 12 | Y33: =OR(S33=X33,S33=W33) -> TRUE | Z33: =U33=1 -> TRUE | AA33: =AND(Z33,Y33) -> TRUE
R34: Neutral | S34: =AH16 -> 15 | T34: =AG17 -> 15 | U34: =S34-T34 -> 0 | W34: 15 | X34: 15 | Y34: =OR(S34=X34,S34=W34) -> TRUE | Z34: =U34=0 -> TRUE | AA34: =AND(Z34,Y34) -> TRUE
A47: Essence | B47: Vibe | C47: Role | D47: Target Offense Score | E47: Target Defense Score | F47: Why
A48: Inferno | B48: Offensive | C48: Burst DPS | D48: High (4–5 2×s) | E48: Low (few resists) | F48: Fire is volatile — should dominate some types, lose to others
A49: Aqua | B49: Balanced | C49: Utility | D49: Medium | E49: Medium | F49: Water is adaptable, good vs Fire but weak to Grass/Electric
A50: Frost | B50: Defensive | C50: Control | D50: Low | E50: High (3–4 resists) | F50: Ice is slow, stall-y, should have bulk but few KOs
A51: Lightning | B51: Offensive | C51: Speed DPS | D51: High (4–5 2×s) | E51: Low (exploitable) | F51: Strikes fast, dies fast
A52: Flora | B52: Support | C52: Status | D52: Medium (3 2×s) | E52: Medium-High | F52: Heals, poisons, slows; not pure damage
A53: Terra | B53: Defensive | C53: Tank | D53: Low | E53: High | F53: Ground is the wall — should null, resist, rarely strike hard
A54: Wind | B54: Evasive | C54: Hit-and-run | D54: Medium | E54: Medium (Nulls OK) | F54: Weak to direct hits but dodges or nullifies
A55: Mind | B55: Strategic | C55: Setup | D55: Medium | E55: Medium | F55: More about position, predictions
...

Sheet Output
B1: Type Matchups Chart (Row = Attacking; Column = Defending)
B2: Inferno | C2: Aqua | D2: Flora | E2: Terra | F2: Wind | G2: Electric | H2: Frost | I2: Mind | J2: Spirit | K2: Cursed | L2: Bless | M2: Mythos | N2: Cyber | O2: Cosmic | P2: Neutral
A3: Inferno | B3: =Input!B2 -> 0.5 | C3: =Input!C2 -> 0.5 | D3: =Input!D2 -> 2 | E3: =Input!E2 -> 2 | F3: =Input!F2 -> 0.5 | G3: =Input!G2 -> 1 | H3: =Input!H2 -> 2 | I3: =Input!I2 -> 1 | ... P3: =Input!P2 -> 1
A4: Aqua | B4: =Input!B3 -> 2 | C4: =Input!C3 -> 0.5 | D4: =Input!D3 -> 0.5 | E4: =Input!E3 -> 2 | F4: =Input!F3 -> 1 | G4: =Input!G3 -> 1 | H4: =Input!H3 -> 0.5 | I4: =Input!I3 -> 1 | ... P4: =Input!P3 -> 1
A5: Flora | B5: =Input!B4 -> 0.5 | C5: =Input!C4 -> 2 | D5: =Input!D4 -> 0.5 | E5: =Input!E4 -> 2 | F5: =Input!F4 -> 0.5 | G5: =Input!G4 -> 1 | H5: =Input!H4 -> 0.5 | I5: =Input!I4 -> 1 | ... P5: =Input!P4 -> 1
A6: Terra | B6: =Input!B5 -> 2 | C6: =Input!C5 -> 1 | D6: =Input!D5 -> 0.5 | E6: =Input!E5 -> 0.5 | F6: =Input!F5 -> 0 | G6: =Input!G5 -> 2 | H6: =Input!H5 -> 0.5 | I6: =Input!I5 -> 0.5 | ... P6: =Input!P5 -> 1
A7: Wind | B7: =Input!B6 -> 2 | C7: =Input!C6 -> 1 | D7: =Input!D6 -> 1 | E7: =Input!E6 -> 0 | F7: =Input!F6 -> 0.5 | G7: =Input!G6 -> 1 | H7: =Input!H6 -> 2 | I7: =Input!I6 -> 1 | ... P7: =Input!P6 -> 1
A8: Electric | B8: =Input!B7 -> 1 | C8: =Input!C7 -> 2 | D8: =Input!D7 -> 1 | E8: =Input!E7 -> 0 | F8: =Input!F7 -> 2 | G8: =Input!G7 -> 0.5 | H8: =Input!H7 -> 0.5 | I8: =Input!I7 -> 0.5 | ... P8: =Input!P7 -> 1
A9: Frost | B9: =Input!B8 -> 0.5 | C9: =Input!C8 -> 0.5 | D9: =Input!D8 -> 2 | E9: =Input!E8 -> 0.5 | F9: =Input!F8 -> 2 | G9: =Input!G8 -> 0.5 | H9: =Input!H8 -> 0.5 | I9: =Input!I8 -> 1 | ... P9: =Input!P8 -> 1
A10: Mind | B10: =Input!B9 -> 2 | C10: =Input!C9 -> 1 | D10: =Input!D9 -> 1 | E10: =Input!E9 -> 0.5 | F10: =Input!F9 -> 2 | G10: =Input!G9 -> 2 | H10: =Input!H9 -> 1 | I10: =Input!I9 -> 1 | ... P10: =Input!P9 -> 1
A11: Spirit | B11: =Input!B10 -> 1 | C11: =Input!C10 -> 1 | D11: =Input!D10 -> 0.5 | E11: =Input!E10 -> 0.5 | F11: =Input!F10 -> 1 | G11: =Input!G10 -> 0.5 | H11: =Input!H10 -> 1 | I11: =Input!I10 -> 2 | ... P11: =Input!P10 -> 1
A12: Cursed | B12: =Input!B11 -> 0.5 | C12: =Input!C11 -> 1 | D12: =Input!D11 -> 1 | E12: =Input!E11 -> 0.5 | F12: =Input!F11 -> 1 | G12: =Input!G11 -> 2 | H12: =Input!H11 -> 1 | I12: =Input!I11 -> 0.5 | ... P12: =Input!P11 -> 1
A13: Bless | B13: =Input!B12 -> 2 | C13: =Input!C12 -> 1 | D13: =Input!D12 -> 1 | E13: =Input!E12 -> 1 | F13: =Input!F12 -> 2 | G13: =Input!G12 -> 0.5 | H13: =Input!H12 -> 0.5 | I13: =Input!I12 -> 0 | ... P13: =Input!P12 -> 1
A14: Mythos | B14: =Input!B13 -> 1 | C14: =Input!C13 -> 1 | D14: =Input!D13 -> 1 | E14: =Input!E13 -> 1 | F14: =Input!F13 -> 2 | G14: =Input!G13 -> 1 | H14: =Input!H13 -> 1 | I14: =Input!I13 -> 2 | ... P14: =Input!P13 -> 1
... A17: Neutral | B17: =Input!B16 -> 1 | C17: =Input!C16 -> 1 | D17: =Input!D16 -> 1 | E17: =Input!E16 -> 1 | F17: =Input!F16 -> 1 | G17: =Input!G16 -> 1 | H17: =Input!H16 -> 1 | I17: =Input!I16 -> 1 | ... P17: =Input!P16 -> 1
B18: Inferno | C18: Aqua | D18: Flora | E18: Terra | F18: Wind | G18: Electric | H18: Frost | I18: Mind | J18: Spirit | K18: Cursed | L18: Bless | M18: Mythos | N18: Cyber | O18: Cosmic | P18: Neutral

Sheet Defensive Summary
A1: Type 1 | B1: Type 2 | C1: Inferno | D1: Aqua | E1: Flora | F1: Terra | G1: Wind | H1: Electric | I1: Frost | J1: Mind | K1: Spirit | L1: Cursed | M1: Bless | N1: Mythos | O1: Cyber | P1: Cosmic | Q1: Neutral | T1: Type 1 | U1: Type 2 | V1: Inferno | W1: Aqua | X1: Flora | Y1: Terra | Z1: Wind | AA1: Electric | AB1: Frost | AC1: Mind | AD1: Spirit | AE1: Cursed | AF1: Bless | AG1: Mythos | AH1: Cyber | AI1: Cosmic | AJ1: Neutral
A2: Inferno | B2: Aqua | C2: =INDEX(Output!$B$3:$P$17,MATCH('Defensive Summary'!C$1,Output!$A$3:$A$17,0),MATCH('Defensive Summary'!$A2,Output!$B$2:$P$2,0))*INDEX(Output!$B$3:$P$17,MATCH('Defensive Summary'!C$1,Output!$A$3:$A$17,0),MATCH('Defensive Summary'!$B2,Output!$B$2:$P$2,0)) -> 0.25 | D2: =INDEX(Output!$B$3:$P$17,MATCH('Defensive Summary'!D$1,Output!$A$3:$A$17,0),MATCH('Defensive Summary'!$A2,Output!$B$2:$P$2,0))*INDEX(Output!$B$3:$P$17,MATCH('Defensive Summary'!D$1,Output!$A$3:$A$17,0),MATCH('Defensive Summary'!$B2,Output!$B$2:$P$2,0)) -> 1 | E2: =INDEX(Output!$B$3:$P$17,MATCH('Defensive Summary'!E$1,Output!$A$3:$A$17,0),MATCH('Defensive Summary'!$A2,Output!$B$2:$P$2,0))*INDEX(Output!$B$3:$P$17,MATCH('Defensive Summary'!E$1,Output!$A$3:$A$17,0),MATCH('Defensive Summary'!$B2,Output!$B$2:$P$2,0)) -> 1 | F2: =INDEX(Output!$B$3:$P$17,MATCH('Defensive Summary'!F$1,Output!$A$3:$A$17,0),MATCH('Defensive Summary'!$A2,Output!$B$2:$P$2,0))*INDEX(Output!$B$3:$P$17,MATCH('Defensive Summary'!F$1,Output!$A$3:$A$17,0),MATCH('Defensive Summary'!$B2,Output!$B$2:$P$2,0)) -> 2 | G2: =INDEX(Output!$B$3:$P$17,MATCH('Defensive Summary'!G$1,Output!$A$3:$A$17,0),MATCH('Defensive Summary'!$A2,Output!$B$2:$P$2,0))*INDEX(Output!$B$3:$P$17,MATCH('Defensive Summary'!G$1,Output!$A$3:$A$17,0),MATCH('Defensive Summary'!$B2,Output!$B$2:$P$2,0)) -> 2 | H2: =INDEX(Output!$B$3:$P$17,MATCH('Defensive Summary'!H$1,Output!$A$3:$A$17,0),MATCH('Defensive Summary'!$A2,Output!$B$2:$P$2,0))*INDEX(Output!$B$3:$P$17,MATCH('Defensive Summary'!H$1,Output!$A$3:$A$17,0),MATCH('Defensive Summary'!$B2,Output!$B$2:$P$2,0)) -> 2 | I2: =INDEX(Output!$B$3:$P$17,MATCH('Defensive Summary'!I$1,Output!$A$3:$A$17,0),MATCH('Defensive Summary'!$A2,Output!$B$2:$P$2,0))*INDEX(Output!$B$3:$P$17,MATCH('Defensive Summary'!I$1,Output!$A$3:$A$17,0),MATCH('Defensive Summary'!$B2,Output!$B$2:$P$2,0)) -> 0.25 | J2: =INDEX(Output!$B$3:$P$17,MATCH('Defensive Summary'!J$1,Output!$A$3:$A$17,0),MATCH('Defensive Summary'!$A2,Output!$B$2:$P$2,0))*INDEX(Output!$B$3:$P$17,MATCH('Defensive Summary'!J$1,Output!$A$3:$A$17,0),MATCH('Defensive Summary'!$B2,Output!$B$2:$P$2,0)) -> 2 | ... Q2: =INDEX(Output!$B$3:$P$17,MATCH('Defensive Summary'!Q$1,Output!$A$3:$A$17,0),MATCH('Defensive Summary'!$A2,Output!$B$2:$P$2,0))*INDEX(Output!$B$3:$P$17,MATCH('Defensive Summary'!Q$1,Output!$A$3:$A$17,0),MATCH('Defensive Summary'!$B2,Output!$B$2:$P$2,0)) -> 1 | S2: =SUM(V2:AJ2) -> 1 | T2: Inferno | U2: Aqua | V2: {=_xlfn.IFS(C2=1,0,C2=2,-1,C2=4,-2,C2=0.5,1,C2=0.25,2,C2=0,4)} -> 2 | W2: {=_xlfn.IFS(D2=1,0,D2=2,-1,D2=4,-2,D2=0.5,1,D2=0.25,2,D2=0,4)} -> 0 | X2: {=_xlfn.IFS(E2=1,0,E2=2,-1,E2=4,-2,E2=0.5,1,E2=0.25,2,E2=0,4)} -> 0 | Y2: {=_xlfn.IFS(F2=1,0,F2=2,-1,F2=4,-2,F2=0.5,1,F2=0.25,2,F2=0,4)} -> -1 | Z2: {=_xlfn.IFS(G2=1,0,G2=2,-1,G2=4,-2,G2=0.5,1,G2=0.25,2,G2=0,4)} -> -1 | AA2: {=_xlfn.IFS(H2=1,0,H2=2,-1,H2=4,-2,H2=0.5,1,H2=0.25,2,H2=0,4)} -> -1 | AB2: {=_xlfn.IFS(I2=1,0,I2=2,-1,I2=4,-2,I2=0.5,1,I2=0.25,2,I2=0,4)} -> 2 | AC2: {=_xlfn.IFS(J2=1,0,J2=2,-1,J2=4,-2,J2=0.5,1,J2=0.25,2,J2=0,4)} -> -1 | ... AJ2: {=_xlfn.IFS(Q2=1,0,Q2=2,-1,Q2=4,-2,Q2=0.5,1,Q2=0.25,2,Q2=0,4)} -> 0
A3: Inferno | B3: Flora | C3: =INDEX(Output!$B$3:$P$17,MATCH('Defensive Summary'!C$1,Output!$A$3:$A$17,0),MATCH('Defensive Summary'!$A3,Output!$B$2:$P$2,0))*INDEX(Output!$B$3:$P$17,MATCH('Defensive Summary'!C$1,Output!$A$3:$A$17,0),MATCH('Defensive Summary'!$B3,Output!$B$2:$P$2,0)) -> 1 | D3: =INDEX(Output!$B$3:$P$17,MATCH('Defensive Summary'!D$1,Output!$A$3:$A$17,0),MATCH('Defensive Summary'!$A3,Output!$B$2:$P$2,0))*INDEX(Output!$B$3:$P$17,MATCH('Defensive Summary'!D$1,Output!$A$3:$A$17,0),MATCH('Defensive Summary'!$B3,Output!$B$2:$P$2,0)) -> 1 | E3: =INDEX(Output!$B$3:$P$17,MATCH('Defensive Summary'!E$1,Output!$A$3:$A$17,0),MATCH('Defensive Summary'!$A3,Output!$B$2:$P$2,0))*INDEX(Output!$B$3:$P$17,MATCH('Defensive Summary'!E$1,Output!$A$3:$A$17,0),MATCH('Defensive Summary'!$B3,Output!$B$2:$P$2,0)) -> 0.25 | F3: =INDEX(Output!$B$3:$P$17,MATCH('Defensive Summary'!F$1,Output!$A$3:$A$17,0),MATCH('Defensive Summary'!$A3,Output!$B$2:$P$2,0))*INDEX(Output!$B$3:$P$17,MATCH('Defensive Summary'!F$1,Output!$A$3:$A$17,0),MATCH('Defensive Summary'!$B3,Output!$B$2:$P$2,0)) -> 1 | G3: =INDEX(Output!$B$3:$P$17,MATCH('Defensive Summary'!G$1,Output!$A$3:$A$17,0),MATCH('Defensive Summary'!$A3,Output!$B$2:$P$2,0))*INDEX(Output!$B$3:$P$17,MATCH('Defensive Summary'!G$1,Output!$A$3:$A$17,0),MATCH('Defensive Summary'!$B3,Output!$B$2:$P$2,0)) -> 2 | H3: =INDEX(Output!$B$3:$P$17,MATCH('Defensive Summary'!H$1,Output!$A$3:$A$17,0),MATCH('Defensive Summary'!$A3,Output!$B$2:$P$2,0))*INDEX(Output!$B$3:$P$17,MATCH('Defensive Summary'!H$1,Output!$A$3:$A$17,0),MATCH('Defensive Summary'!$B3,Output!$B$2:$P$2,0)) -> 1 | I3: =INDEX(Output!$B$3:$P$17,MATCH('Defensive Summary'!I$1,Output!$A$3:$A$17,0),MATCH('Defensive Summary'!$A3,Output!$B$2:$P$2,0))*INDEX(Output!$B$3:$P$17,MATCH('Defensive Summary'!I$1,Output!$A$3:$A$17,0),MATCH('Defensive Summary'!$B3,Output!$B$2:$P$2,0)) -> 1 | J3: =INDEX(Output!$B$3:$P$17,MATCH('Defensive Summary'!J$1,Output!$A$3:$A$17,0),MATCH('Defensive Summary'!$A3,Output!$B$2:$P$2,0))*INDEX(Output!$B$3:$P$17,MATCH('Defensive Summary'!J$1,Output!$A$3:$A$17,0),MATCH('Defensive Summary'!$B3,Output!$B$2:$P$2,0)) -> 2 | ... Q3: =INDEX(Output!$B$3:$P$17,MATCH('Defensive Summary'!Q$1,Output!$A$3:$A$17,0),MATCH('Defensive Summary'!$A3,Output!$B$2:$P$2,0))*INDEX(Output!$B$3:$P$17,MATCH('Defensive Summary'!Q$1,Output!$A$3:$A$17,0),MATCH('Defensive Summary'!$B3,Output!$B$2:$P$2,0)) -> 1 | S3: =SUM(V3:AJ3) -> 1 | T3: Inferno | U3: Flora | V3: {=_xlfn.IFS(C3=1,0,C3=2,-1,C3=4,-2,C3=0.5,1,C3=0.25,2,C3=0,4)} -> 0 | W3: {=_xlfn.IFS(D3=1,0,D3=2,-1,D3=4,-2,D3=0.5,1,D3=0.25,2,D3=0,4)} -> 0 | X3: {=_xlfn.IFS(E3=1,0,E3=2,-1,E3=4,-2,E3=0.5,1,E3=0.25,2,E3=0,4)} -> 2 | Y3: {=_xlfn.IFS(F3=1,0,F3=2,-1,F3=4,-2,F3=0.5,1,F3=0.25,2,F3=0,4)} -> 0 | Z3: {=_xlfn.IFS(G3=1,0,G3=2,-1,G3=4,-2,G3=0.5,1,G3=0.25,2,G3=0,4)} -> -1 | AA3: {=_xlfn.IFS(H3=1,0,H3=2,-1,H3=4,-2,H3=0.5,1,H3=0.25,2,H3=0,4)} -> 0 | AB3: {=_xlfn.IFS(I3=1,0,I3=2,-1,I3=4,-2,I3=0.5,1,I3=0.25,2,I3=0,4)} -> 0 | AC3: {=_xlfn.IFS(J3=1,0,J3=2,-1,J3=4,-2,J3=0.5,1,J3=0.25,2,J3=0,4)} -> -1 | ... AJ3: {=_xlfn.IFS(Q3=1,0,Q3=2,-1,Q3=4,-2,Q3=0.5,1,Q3=0.25,2,Q3=0,4)} -> 0
A4: Inferno | B4: Terra | C4: =INDEX(Output!$B$3:$P$17,MATCH('Defensive Summary'!C$1,Output!$A$3:$A$17,0),MATCH('Defensive Summary'!$A4,Output!$B$2:$P$2,0))*INDEX(Output!$B$3:$P$17,MATCH('Defensive Summary'!C$1,Output!$A$3:$A$17,0),MATCH('Defensive Summary'!$B4,Output!$B$2:$P$2,0)) -> 1 | D4: =INDEX(Output!$B$3:$P$17,MATCH('Defensive Summary'!D$1,Output!$A$3:$A$17,0),MATCH('Defensive Summary'!$A4,Output!$B$2:$P$2,0))*INDEX(Output!$B$3:$P$17,MATCH('Defensive Summary'!D$1,Output!$A$3:$A$17,0),MATCH('Defensive Summary'!$B4,Output!$B$2:$P$2,0)) -> 4 | E4: =INDEX(Output!$B$3:$P$17,MATCH('Defensive Summary'!E$1,Output!$A$3:$A$17,0),MATCH('Defensive Summary'!$A4,Output!$B$2:$P$2,0))*INDEX(Output!$B$3:$P$17,MATCH('Defensive Summary'!E$1,Output!$A$3:$A$17,0),MATCH('Defensive Summary'!$B4,Output!$B$2:$P$2,0)) -> 1 | F4: =INDEX(Output!$B$3:$P$17,MATCH('Defensive Summary'!F$1,Output!$A$3:$A$17,0),MATCH('Defensive Summary'!$A4,Output!$B$2:$P$2,0))*INDEX(Output!$B$3:$P$17,MATCH('Defensive Summary'!F$1,Output!$A$3:$A$17,0),MATCH('Defensive Summary'!$B4,Output!$B$2:$P$2,0)) -> 1 | G4: =INDEX(Output!$B$3:$P$17,MATCH('Defensive Summary'!G$1,Output!$A$3:$A$17,0),MATCH('Defensive Summary'!$A4,Output!$B$2:$P$2,0))*INDEX(Output!$B$3:$P$17,MATCH('Defensive Summary'!G$1,Output!$A$3:$A$17,0),MATCH('Defensive Summary'!$B4,Output!$B$2:$P$2,0)) -> 0 | H4: =INDEX(Output!$B$3:$P$17,MATCH('Defensive Summary'!H$1,Output!$A$3:$A$17,0),MATCH('Defensive Summary'!$A4,Output!$B$2:$P$2,0))*INDEX(Output!$B$3:$P$17,MATCH('Defensive Summary'!H$1,Output!$A$3:$A$17,0),MATCH('Defensive Summary'!$B4,Output!$B$2:$P$2,0)) -> 0 | I4: =INDEX(Output!$B$3:$P$17,MATCH('Defensive Summary'!I$1,Output!$A$3:$A$17,0),MATCH('Defensive Summary'!$A4,Output!$B$2:$P$2,0))*INDEX(Output!$B$3:$P$17,MATCH('Defensive Summary'!I$1,Output!$A$3:$A$17,0),MATCH('Defensive Summary'!$B4,Output!$B$2:$P$2,0)) -> 0.25 | J4: =INDEX(Output!$B$3:$P$17,MATCH('Defensive Summary'!J$1,Output!$A$3:$A$17,0),MATCH('Defensive Summary'!$A4,Output!$B$2:$P$2,0))*INDEX(Output!$B$3:$P$17,MATCH('Defensive Summary'!J$1,Output!$A$3:$A$17,0),MATCH('Defensive Summary'!$B4,Output!$B$2:$P$2,0)) -> 1 | ... Q4: =INDEX(Output!$B$3:$P$17,MATCH('Defensive Summary'!Q$1,Output!$A$3:$A$17,0),MATCH('Defensive Summary'!$A4,Output!$B$2:$P$2,0))*INDEX(Output!$B$3:$P$17,MATCH('Defensive Summary'!Q$1,Output!$A$3:$A$17,0),MATCH('Defensive Summary'!$B4,Output!$B$2:$P$2,0)) -> 1 | S4: =SUM(V4:AJ4) -> 10 | T4: Inferno | U4: Terra | V4: {=_xlfn.IFS(C4=1,0,C4=2,-1,C4=4,-2,C4=0.5,1,C4=0.25,2,C4=0,4)} -> 0 | W4: {=_xlfn.IFS(D4=1,0,D4=2,-1,D4=4,-2,D4=0.5,1,D4=0.25,2,D4=0,4)} -> -2 | X4: {=_xlfn.IFS(E4=1,0,E4=2,-1,E4=4,-2,E4=0.5,1,E4=0.25,2,E4=0,4)} -> 0 | Y4: {=_xlfn.IFS(F4=1,0,F4=2,-1,F4=4,-2,F4=0.5,1,F4=0.25,2,F4=0,4)} -> 0 | Z4: {=_xlfn.IFS(G4=1,0,G4=2,-1,G4=4,-2,G4=0.5,1,G4=0.25,2,G4=0,4)} -> 4 | AA4: {=_xlfn.IFS(H4=1,0,H4=2,-1,H4=4,-2,H4=0.5,1,H4=0.25,2,H4=0,4)} -> 4 | AB4: {=_xlfn.IFS(I4=1,0,I4=2,-1,I4=4,-2,I4=0.5,1,I4=0.25,2,I4=0,4)} -> 2 | AC4: {=_xlfn.IFS(J4=1,0,J4=2,-1,J4=4,-2,J4=0.5,1,J4=0.25,2,J4=0,4)} -> 0 | ... AJ4: {=_xlfn.IFS(Q4=1,0,Q4=2,-1,Q4=4,-2,Q4=0.5,1,Q4=0.25,2,Q4=0,4)} -> 0
A5: Inferno | B5: Wind | C5: =INDEX(Output!$B$3:$P$17,MATCH('Defensive Summary'!C$1,Output!$A$3:$A$17,0),MATCH('Defensive Summary'!$A5,Output!$B$2:$P$2,0))*INDEX(Output!$B$3:$P$17,MATCH('Defensive Summary'!C$1,Output!$A$3:$A$17,0),MATCH('Defensive Summary'!$B5,Output!$B$2:$P$2,0)) -> 0.25 | D5: =INDEX(Output!$B$3:$P$17,MATCH('Defensive Summary'!D$1,Output!$A$3:$A$17,0),MATCH('Defensive Summary'!$A5,Output!$B$2:$P$2,0))*INDEX(Output!$B$3:$P$17,MATCH('Defensive Summary'!D$1,Output!$A$3:$A$17,0),MATCH('Defensive Summary'!$B5,Output!$B$2:$P$2,0)) -> 2 | E5: =INDEX(Output!$B$3:$P$17,MATCH('Defensive Summary'!E$1,Output!$A$3:$A$17,0),MATCH('Defensive Summary'!$A5,Output!$B$2:$P$2,0))*INDEX(Output!$B$3:$P$17,MATCH('Defensive Summary'!E$1,Output!$A$3:$A$17,0),MATCH('Defensive Summary'!$B5,Output!$B$2:$P$2,0)) -> 0.25 | F5: =INDEX(Output!$B$3:$P$17,MATCH('Defensive Summary'!F$1,Output!$A$3:$A$17,0),MATCH('Defensive Summary'!$A5,Output!$B$2:$P$2,0))*INDEX(Output!$B$3:$P$17,MATCH('Defensive Summary'!F$1,Output!$A$3:$A$17,0),MATCH('Defensive Summary'!$B5,Output!$B$2:$P$2,0)) -> 0 | G5: =INDEX(Output!$B$3:$P$17,MATCH('Defensive Summary'!G$1,Output!$A$3:$A$17,0),MATCH('Defensive Summary'!$A5,Output!$B$2:$P$2,0))*INDEX(Output!$B$3:$P$17,MATCH('Defensive Summary'!G$1,Output!$A$3:$A$17,0),MATCH('Defensive Summary'!$B5,Output!$B$2:$P$2,0)) -> 1 | H5: =INDEX(Output!$B$3:$P$17,MATCH('Defensive Summary'!H$1,Output!$A$3:$A$17,0),MATCH('Defensive Summary'!$A5,Output!$B$2:$P$2,0))*INDEX(Output!$B$3:$P$17,MATCH('Defensive Summary'!H$1,Output!$A$3:$A$17,0),MATCH('Defensive Summary'!$B5,Output!$B$2:$P$2,0)) -> 2 | I5: =INDEX(Output!$B$3:$P$17,MATCH('Defensive Summary'!I$1,Output!$A$3:$A$17,0),MATCH('Defensive Summary'!$A5,Output!$B$2:$P$2,0))*INDEX(Output!$B$3:$P$17,MATCH('Defensive Summary'!I$1,Output!$A$3:$A$17,0),MATCH('Defensive Summary'!$B5,Output!$B$2:$P$2,0)) -> 1 | J5: =INDEX(Output!$B$3:$P$17,MATCH('Defensive Summary'!J$1,Output!$A$3:$A$17,0),MATCH('Defensive Summary'!$A5,Output!$B$2:$P$2,0))*INDEX(Output!$B$3:$P$17,MATCH('Defensive Summary'!J$1,Output!$A$3:$A$17,0),MATCH('Defensive Summary'!$B5,Output!$B$2:$P$2,0)) -> 4 | ... Q5: =INDEX(Output!$B$3:$P$17,MATCH('Defensive Summary'!Q$1,Output!$A$3:$A$17,0),MATCH('Defensive Summary'!$A5,Output!$B$2:$P$2,0))*INDEX(Output!$B$3:$P$17,MATCH('Defensive Summary'!Q$1,Output!$A$3:$A$17,0),MATCH('Defensive Summary'!$B5,Output!$B$2:$P$2,0)) -> 1 | S5: =SUM(V5:AJ5) -> 1 | T5: Inferno | U5: Wind | V5: {=_xlfn.IFS(C5=1,0,C5=2,-1,C5=4,-2,C5=0.5,1,C5=0.25,2,C5=0,4)} -> 2 | W5: {=_xlfn.IFS(D5=1,0,D5=2,-1,D5=4,-2,D5=0.5,1,D5=0.25,2,D5=0,4)} -> -1 | X5: {=_xlfn.IFS(E5=1,0,E5=2,-1,E5=4,-2,E5=0.5,1,E5=0.25,2,E5=0,4)} -> 2 | Y5: {=_xlfn.IFS(F5=1,0,F5=2,-1,F5=4,-2,F5=0.5,1,F5=0.25,2,F5=0,4)} -> 4 | Z5: {=_xlfn.IFS(G5=1,0,G5=2,-1,G5=4,-2,G5=0.5,1,G5=0.25,2,G5=0,4)} -> 0 | AA5: {=_xlfn.IFS(H5=1,0,H5=2,-1,H5=4,-2,H5=0.5,1,H5=0.25,2,H5=0,4)} -> -1 | AB5: {=_xlfn.IFS(I5=1,0,I5=2,-1,I5=4,-2,I5=0.5,1,I5=0.25,2,I5=0,4)} -> 0 | AC5: {=_xlfn.IFS(J5=1,0,J5=2,-1,J5=4,-2,J5=0.5,1,J5=0.25,2,J5=0,4)} -> -2 | ... AJ5: {=_xlfn.IFS(Q5=1,0,Q5=2,-1,Q5=4,-2,Q5=0.5,1,Q5=0.25,2,Q5=0,4)} -> 0
A6: Inferno | B6: Electric | C6: =INDEX(Output!$B$3:$P$17,MATCH('Defensive Summary'!C$1,Output!$A$3:$A$17,0),MATCH('Defensive Summary'!$A6,Output!$B$2:$P$2,0))*INDEX(Output!$B$3:$P$17,MATCH('Defensive Summary'!C$1,Output!$A$3:$A$17,0),MATCH('Defensive Summary'!$B6,Output!$B$2:$P$2,0)) -> 0.5 | D6: =INDEX(Output!$B$3:$P$17,MATCH('Defensive Summary'!D$1,Output!$A$3:$A$17,0),MATCH('Defensive Summary'!$A6,Output!$B$2:$P$2,0))*INDEX(Output!$B$3:$P$17,MATCH('Defensive Summary'!D$1,Output!$A$3:$A$17,0),MATCH('Defensive Summary'!$B6,Output!$B$2:$P$2,0)) -> 2 | E6: =INDEX(Output!$B$3:$P$17,MATCH('Defensive Summary'!E$1,Output!$A$3:$A$17,0),MATCH('Defensive Summary'!$A6,Output!$B$2:$P$2,0))*INDEX(Output!$B$3:$P$17,MATCH('Defensive Summary'!E$1,Output!$A$3:$A$17,0),MATCH('Defensive Summary'!$B6,Output!$B$2:$P$2,0)) -> 0.5 | F6: =INDEX(Output!$B$3:$P$17,MATCH('Defensive Summary'!F$1,Output!$A$3:$A$17,0),MATCH('Defensive Summary'!$A6,Output!$B$2:$P$2,0))*INDEX(Output!$B$3:$P$17,MATCH('Defensive Summary'!F$1,Output!$A$3:$A$17,0),MATCH('Defensive Summary'!$B6,Output!$B$2:$P$2,0)) -> 4 | G6: =INDEX(Output!$B$3:$P$17,MATCH('Defensive Summary'!G$1,Output!$A$3:$A$17,0),MATCH('Defensive Summary'!$A6,Output!$B$2:$P$2,0))*INDEX(Output!$B$3:$P$17,MATCH('Defensive Summary'!G$1,Output!$A$3:$A$17,0),MATCH('Defensive Summary'!$B6,Output!$B$2:$P$2,0)) -> 2 | H6: =INDEX(Output!$B$3:$P$17,MATCH('Defensive Summary'!H$1,Output!$A$3:$A$17,0),MATCH('Defensive Summary'!$A6,Output!$B$2:$P$2,0))*INDEX(Output!$B$3:$P$17,MATCH('Defensive Summary'!H$1,Output!$A$3:$A$17,0),MATCH('Defensive Summary'!$B6,Output!$B$2:$P$2,0)) -> 0.5 | I6: =INDEX(Output!$B$3:$P$17,MATCH('Defensive Summary'!I$1,Output!$A$3:$A$17,0),MATCH('Defensive Summary'!$A6,Output!$B$2:$P$2,0))*INDEX(Output!$B$3:$P$17,MATCH('Defensive Summary'!I$1,Output!$A$3:$A$17,0),MATCH('Defensive Summary'!$B6,Output!$B$2:$P$2,0)) -> 0.25 | J6: =INDEX(Output!$B$3:$P$17,MATCH('Defensive Summary'!J$1,Output!$A$3:$A$17,0),MATCH('Defensive Summary'!$A6,Output!$B$2:$P$2,0))*INDEX(Output!$B$3:$P$17,MATCH('Defensive Summary'!J$1,Output!$A$3:$A$17,0),MATCH('Defensive Summary'!$B6,Output!$B$2:$P$2,0)) -> 4 | ... Q6: =INDEX(Output!$B$3:$P$17,MATCH('Defensive Summary'!Q$1,Output!$A$3:$A$17,0),MATCH('Defensive Summary'!$A6,Output!$B$2:$P$2,0))*INDEX(Output!$B$3:$P$17,MATCH('Defensive Summary'!Q$1,Output!$A$3:$A$17,0),MATCH('Defensive Summary'!$B6,Output!$B$2:$P$2,0)) -> 1 | S6: =SUM(V6:AJ6) -> 0 | T6: Inferno | U6: Electric | V6: {=_xlfn.IFS(C6=1,0,C6=2,-1,C6=4,-2,C6=0.5,1,C6=0.25,2,C6=0,4)} -> 1 | W6: {=_xlfn.IFS(D6=1,0,D6=2,-1,D6=4,-2,D6=0.5,1,D6=0.25,2,D6=0,4)} -> -1 | X6: {=_xlfn.IFS(E6=1,0,E6=2,-1,E6=4,-2,E6=0.5,1,E6=0.25,2,E6=0,4)} -> 1 | Y6: {=_xlfn.IFS(F6=1,0,F6=2,-1,F6=4,-2,F6=0.5,1,F6=0.25,2,F6=0,4)} -> -2 | Z6: {=_xlfn.IFS(G6=1,0,G6=2,-1,G6=4,-2,G6=0.5,1,G6=0.25,2,G6=0,4)} -> -1 | AA6: {=_xlfn.IFS(H6=1,0,H6=2,-1,H6=4,-2,H6=0.5,1,H6=0.25,2,H6=0,4)} -> 1 | AB6: {=_xlfn.IFS(I6=1,0,I6=2,-1,I6=4,-2,I6=0.5,1,I6=0.25,2,I6=0,4)} -> 2 | AC6: {=_xlfn.IFS(J6=1,0,J6=2,-1,J6=4,-2,J6=0.5,1,J6=0.25,2,J6=0,4)} -> -2 | ... AJ6: {=_xlfn.IFS(Q6=1,0,Q6=2,-1,Q6=4,-2,Q6=0.5,1,Q6=0.25,2,Q6=0,4)} -> 0
A7: Inferno | B7: Frost | C7: =INDEX(Output!$B$3:$P$17,MATCH('Defensive Summary'!C$1,Output!$A$3:$A$17,0),MATCH('Defensive Summary'!$A7,Output!$B$2:$P$2,0))*INDEX(Output!$B$3:$P$17,MATCH('Defensive Summary'!C$1,Output!$A$3:$A$17,0),MATCH('Defensive Summary'!$B7,Output!$B$2:$P$2,0)) -> 1 | D7: =INDEX(Output!$B$3:$P$17,MATCH('Defensive Summary'!D$1,Output!$A$3:$A$17,0),MATCH('Defensive Summary'!$A7,Output!$B$2:$P$2,0))*INDEX(Output!$B$3:$P$17,MATCH('Defensive Summary'!D$1,Output!$A$3:$A$17,0),MATCH('Defensive Summary'!$B7,Output!$B$2:$P$2,0)) -> 1 | E7: =INDEX(Output!$B$3:$P$17,MATCH('Defensive Summary'!E$1,Output!$A$3:$A$17,0),MATCH('Defensive Summary'!$A7,Output!$B$2:$P$2,0))*INDEX(Output!$B$3:$P$17,MATCH('Defensive Summary'!E$1,Output!$A$3:$A$17,0),MATCH('Defensive Summary'!$B7,Output!$B$2:$P$2,0)) -> 0.25 | F7: =INDEX(Output!$B$3:$P$17,MATCH('Defensive Summary'!F$1,Output!$A$3:$A$17,0),MATCH('Defensive Summary'!$A7,Output!$B$2:$P$2,0))*INDEX(Output!$B$3:$P$17,MATCH('Defensive Summary'!F$1,Output!$A$3:$A$17,0),MATCH('Defensive Summary'!$B7,Output!$B$2:$P$2,0)) -> 1 | G7: =INDEX(Output!$B$3:$P$17,MATCH('Defensive Summary'!G$1,Output!$A$3:$A$17,0),MATCH('Defensive Summary'!$A7,Output!$B$2:$P$2,0))*INDEX(Output!$B$3:$P$17,MATCH('Defensive Summary'!G$1,Output!$A$3:$A$17,0),MATCH('Defensive Summary'!$B7,Output!$B$2:$P$2,0)) -> 4 | H7: =INDEX(Output!$B$3:$P$17,MATCH('Defensive Summary'!H$1,Output!$A$3:$A$17,0),MATCH('Defensive Summary'!$A7,Output!$B$2:$P$2,0))*INDEX(Output!$B$3:$P$17,MATCH('Defensive Summary'!H$1,Output!$A$3:$A$17,0),MATCH('Defensive Summary'!$B7,Output!$B$2:$P$2,0)) -> 0.5 | I7: =INDEX(Output!$B$3:$P$17,MATCH('Defensive Summary'!I$1,Output!$A$3:$A$17,0),MATCH('Defensive Summary'!$A7,Output!$B$2:$P$2,0))*INDEX(Output!$B$3:$P$17,MATCH('Defensive Summary'!I$1,Output!$A$3:$A$17,0),MATCH('Defensive Summary'!$B7,Output!$B$2:$P$2,0)) -> 0.25 | J7: =INDEX(Output!$B$3:$P$17,MATCH('Defensive Summary'!J$1,Output!$A$3:$A$17,0),MATCH('Defensive Summary'!$A7,Output!$B$2:$P$2,0))*INDEX(Output!$B$3:$P$17,MATCH('Defensive Summary'!J$1,Output!$A$3:$A$17,0),MATCH('Defensive Summary'!$B7,Output!$B$2:$P$2,0)) -> 2 | ... Q7: =INDEX(Output!$B$3:$P$17,MATCH('Defensive Summary'!Q$1,Output!$A$3:$A$17,0),MATCH('Defensive Summary'!$A7,Output!$B$2:$P$2,0))*INDEX(Output!$B$3:$P$17,MATCH('Defensive Summary'!Q$1,Output!$A$3:$A$17,0),MATCH('Defensive Summary'!$B7,Output!$B$2:$P$2,0)) -> 1 | S7: =SUM(V7:AJ7) -> 4 | T7: Inferno | U7: Frost | V7: {=_xlfn.IFS(C7=1,0,C7=2,-1,C7=4,-2,C7=0.5,1,C7=0.25,2,C7=0,4)} -> 0 | W7: {=_xlfn.IFS(D7=1,0,D7=2,-1,D7=4,-2,D7=0.5,1,D7=0.25,2,D7=0,4)} -> 0 | X7: {=_xlfn.IFS(E7=1,0,E7=2,-1,E7=4,-2,E7=0.5,1,E7=0.25,2,E7=0,4)} -> 2 | Y7: {=_xlfn.IFS(F7=1,0,F7=2,-1,F7=4,-2,F7=0.5,1,F7=0.25,2,F7=0,4)} -> 0 | Z7: {=_xlfn.IFS(G7=1,0,G7=2,-1,G7=4,-2,G7=0.5,1,G7=0.25,2,G7=0,4)} -> -2 | AA7: {=_xlfn.IFS(H7=1,0,H7=2,-1,H7=4,-2,H7=0.5,1,H7=0.25,2,H7=0,4)} -> 1 | AB7: {=_xlfn.IFS(I7=1,0,I7=2,-1,I7=4,-2,I7=0.5,1,I7=0.25,2,I7=0,4)} -> 2 | AC7: {=_xlfn.IFS(J7=1,0,J7=2,-1,J7=4,-2,J7=0.5,1,J7=0.25,2,J7=0,4)} -> -1 | ... AJ7: {=_xlfn.IFS(Q7=1,0,Q7=2,-1,Q7=4,-2,Q7=0.5,1,Q7=0.25,2,Q7=0,4)} -> 0
A8: Inferno | B8: Mind | C8: =INDEX(Output!$B$3:$P$17,MATCH('Defensive Summary'!C$1,Output!$A$3:$A$17,0),MATCH('Defensive Summary'!$A8,Output!$B$2:$P$2,0))*INDEX(Output!$B$3:$P$17,MATCH('Defensive Summary'!C$1,Output!$A$3:$A$17,0),MATCH('Defensive Summary'!$B8,Output!$B$2:$P$2,0)) -> 0.5 | D8: =INDEX(Output!$B$3:$P$17,MATCH('Defensive Summary'!D$1,Output!$A$3:$A$17,0),MATCH('Defensive Summary'!$A8,Output!$B$2:$P$2,0))*INDEX(Output!$B$3:$P$17,MATCH('Defensive Summary'!D$1,Output!$A$3:$A$17,0),MATCH('Defensive Summary'!$B8,Output!$B$2:$P$2,0)) -> 2 | E8: =INDEX(Output!$B$3:$P$17,MATCH('Defensive Summary'!E$1,Output!$A$3:$A$17,0),MATCH('Defensive Summary'!$A8,Output!$B$2:$P$2,0))*INDEX(Output!$B$3:$P$17,MATCH('Defensive Summary'!E$1,Output!$A$3:$A$17,0),MATCH('Defensive Summary'!$B8,Output!$B$2:$P$2,0)) -> 0.5 | F8: =INDEX(Output!$B$3:$P$17,MATCH('Defensive Summary'!F$1,Output!$A$3:$A$17,0),MATCH('Defensive Summary'!$A8,Output!$B$2:$P$2,0))*INDEX(Output!$B$3:$P$17,MATCH('Defensive Summary'!F$1,Output!$A$3:$A$17,0),MATCH('Defensive Summary'!$B8,Output!$B$2:$P$2,0)) -> 1 | G8: =INDEX(Output!$B$3:$P$17,MATCH('Defensive Summary'!G$1,Output!$A$3:$A$17,0),MATCH('Defensive Summary'!$A8,Output!$B$2:$P$2,0))*INDEX(Output!$B$3:$P$17,MATCH('Defensive Summary'!G$1,Output!$A$3:$A$17,0),MATCH('Defensive Summary'!$B8,Output!$B$2:$P$2,0)) -> 2 | H8: =INDEX(Output!$B$3:$P$17,MATCH('Defensive Summary'!H$1,Output!$A$3:$A$17,0),MATCH('Defensive Summary'!$A8,Output!$B$2:$P$2,0))*INDEX(Output!$B$3:$P$17,MATCH('Defensive Summary'!H$1,Output!$A$3:$A$17,0),MATCH('Defensive Summary'!$B8,Output!$B$2:$P$2,0)) -> 0.5 | I8: =INDEX(Output!$B$3:$P$17,MATCH('Defensive Summary'!I$1,Output!$A$3:$A$17,0),MATCH('Defensive Summary'!$A8,Output!$B$2:$P$2,0))*INDEX(Output!$B$3:$P$17,MATCH('Defensive Summary'!I$1,Output!$A$3:$A$17,0),MATCH('Defensive Summary'!$B8,Output!$B$2:$P$2,0)) -> 0.5 | J8: =INDEX(Output!$B$3:$P$17,MATCH('Defensive Summary'!J$1,Output!$A$3:$A$17,0),MATCH('Defensive Summary'!$A8,Output!$B$2:$P$2,0))*INDEX(Output!$B$3:$P$17,MATCH('Defensive Summary'!J$1,Output!$A$3:$A$17,0),MATCH('Defensive Summary'!$B8,Output!$B$2:$P$2,0)) -> 2 | ... Q8: =INDEX(Output!$B$3:$P$17,MATCH('Defensive Summary'!Q$1,Output!$A$3:$A$17,0),MATCH('Defensive Summary'!$A8,Output!$B$2:$P$2,0))*INDEX(Output!$B$3:$P$17,MATCH('Defensive Summary'!Q$1,Output!$A$3:$A$17,0),MATCH('Defensive Summary'!$B8,Output!$B$2:$P$2,0)) -> 1 | S8: =SUM(V8:AJ8) -> 3 | T8: Inferno | U8: Mind | V8: {=_xlfn.IFS(C8=1,0,C8=2,-1,C8=4,-2,C8=0.5,1,C8=0.25,2,C8=0,4)} -> 1 | W8: {=_xlfn.IFS(D8=1,0,D8=2,-1,D8=4,-2,D8=0.5,1,D8=0.25,2,D8=0,4)} -> -1 | X8: {=_xlfn.IFS(E8=1,0,E8=2,-1,E8=4,-2,E8=0.5,1,E8=0.25,2,E8=0,4)} -> 1 | Y8: {=_xlfn.IFS(F8=1,0,F8=2,-1,F8=4,-2,F8=0.5,1,F8=0.25,2,F8=0,4)} -> 0 | Z8: {=_xlfn.IFS(G8=1,0,G8=2,-1,G8=4,-2,G8=0.5,1,G8=0.25,2,G8=0,4)} -> -1 | AA8: {=_xlfn.IFS(H8=1,0,H8=2,-1,H8=4,-2,H8=0.5,1,H8=0.25,2,H8=0,4)} -> 1 | AB8: {=_xlfn.IFS(I8=1,0,I8=2,-1,I8=4,-2,I8=0.5,1,I8=0.25,2,I8=0,4)} -> 1 | AC8: {=_xlfn.IFS(J8=1,0,J8=2,-1,J8=4,-2,J8=0.5,1,J8=0.25,2,J8=0,4)} -> -1 | ... AJ8: {=_xlfn.IFS(Q8=1,0,Q8=2,-1,Q8=4,-2,Q8=0.5,1,Q8=0.25,2,Q8=0,4)} -> 0
A9: Inferno | B9: Spirit | C9: =INDEX(Output!$B$3:$P$17,MATCH('Defensive Summary'!C$1,Output!$A$3:$A$17,0),MATCH('Defensive Summary'!$A9,Output!$B$2:$P$2,0))*INDEX(Output!$B$3:$P$17,MATCH('Defensive Summary'!C$1,Output!$A$3:$A$17,0),MATCH('Defensive Summary'!$B9,Output!$B$2:$P$2,0)) -> 0.25 | D9: =INDEX(Output!$B$3:$P$17,MATCH('Defensive Summary'!D$1,Output!$A$3:$A$17,0),MATCH('Defensive Summary'!$A9,Output!$B$2:$P$2,0))*INDEX(Output!$B$3:$P$17,MATCH('Defensive Summary'!D$1,Output!$A$3:$A$17,0),MATCH('Defensive Summary'!$B9,Output!$B$2:$P$2,0)) -> 1 | E9: =INDEX(Output!$B$3:$P$17,MATCH('Defensive Summary'!E$1,Output!$A$3:$A$17,0),MATCH('Defensive Summary'!$A9,Output!$B$2:$P$2,0))*INDEX(Output!$B$3:$P$17,MATCH('Defensive Summary'!E$1,Output!$A$3:$A$17,0),MATCH('Defensive Summary'!$B9,Output!$B$2:$P$2,0)) -> 0.5 | F9: =INDEX(Output!$B$3:$P$17,MATCH('Defensive Summary'!F$1,Output!$A$3:$A$17,0),MATCH('Defensive Summary'!$A9,Output!$B$2:$P$2,0))*INDEX(Output!$B$3:$P$17,MATCH('Defensive Summary'!F$1,Output!$A$3:$A$17,0),MATCH('Defensive Summary'!$B9,Output!$B$2:$P$2,0)) -> 1 | G9: =INDEX(Output!$B$3:$P$17,MATCH('Defensive Summary'!G$1,Output!$A$3:$A$17,0),MATCH('Defensive Summary'!$A9,Output!$B$2:$P$2,0))*INDEX(Output!$B$3:$P$17,MATCH('Defensive Summary'!G$1,Output!$A$3:$A$17,0),MATCH('Defensive Summary'!$B9,Output!$B$2:$P$2,0)) -> 4 | H9: =INDEX(Output!$B$3:$P$17,MATCH('Defensive Summary'!H$1,Output!$A$3:$A$17,0),MATCH('Defensive Summary'!$A9,Output!$B$2:$P$2,0))*INDEX(Output!$B$3:$P$17,MATCH('Defensive Summary'!H$1,Output!$A$3:$A$17,0),MATCH('Defensive Summary'!$B9,Output!$B$2:$P$2,0)) -> 2 | I9: =INDEX(Output!$B$3:$P$17,MATCH('Defensive Summary'!I$1,Output!$A$3:$A$17,0),MATCH('Defensive Summary'!$A9,Output!$B$2:$P$2,0))*INDEX(Output!$B$3:$P$17,MATCH('Defensive Summary'!I$1,Output!$A$3:$A$17,0),MATCH('Defensive Summary'!$B9,Output!$B$2:$P$2,0)) -> 0.5 | J9: =INDEX(Output!$B$3:$P$17,MATCH('Defensive Summary'!J$1,Output!$A$3:$A$17,0),MATCH('Defensive Summary'!$A9,Output!$B$2:$P$2,0))*INDEX(Output!$B$3:$P$17,MATCH('Defensive Summary'!J$1,Output!$A$3:$A$17,0),MATCH('Defensive Summary'!$B9,Output!$B$2:$P$2,0)) -> 0 | ... Q9: =INDEX(Output!$B$3:$P$17,MATCH('Defensive Summary'!Q$1,Output!$A$3:$A$17,0),MATCH('Defensive Summary'!$A9,Output!$B$2:$P$2,0))*INDEX(Output!$B$3:$P$17,MATCH('Defensive Summary'!Q$1,Output!$A$3:$A$17,0),MATCH('Defensive Summary'!$B9,Output!$B$2:$P$2,0)) -> 1 | S9: =SUM(V9:AJ9) -> 6 | T9: Inferno | U9: Spirit | V9: {=_xlfn.IFS(C9=1,0,C9=2,-1,C9=4,-2,C9=0.5,1,C9=0.25,2,C9=0,4)} -> 2 | W9: {=_xlfn.IFS(D9=1,0,D9=2,-1,D9=4,-2,D9=0.5,1,D9=0.25,2,D9=0,4)} -> 0 | X9: {=_xlfn.IFS(E9=1,0,E9=2,-1,E9=4,-2,E9=0.5,1,E9=0.25,2,E9=0,4)} -> 1 | Y9: {=_xlfn.IFS(F9=1,0,F9=2,-1,F9=4,-2,F9=0.5,1,F9=0.25,2,F9=0,4)} -> 0 | Z9: {=_xlfn.IFS(G9=1,0,G9=2,-1,G9=4,-2,G9=0.5,1,G9=0.25,2,G9=0,4)} -> -2 | AA9: {=_xlfn.IFS(H9=1,0,H9=2,-1,H9=4,-2,H9=0.5,1,H9=0.25,2,H9=0,4)} -> -1 | AB9: {=_xlfn.IFS(I9=1,0,I9=2,-1,I9=4,-2,I9=0.5,1,I9=0.25,2,I9=0,4)} -> 1 | AC9: {=_xlfn.IFS(J9=1,0,J9=2,-1,J9=4,-2,J9=0.5,1,J9=0.25,2,J9=0,4)} -> 4 | ... AJ9: {=_xlfn.IFS(Q9=1,0,Q9=2,-1,Q9=4,-2,Q9=0.5,1,Q9=0.25,2,Q9=0,4)} -> 0
A10: Inferno | B10: Cursed | C10: =INDEX(Output!$B$3:$P$17,MATCH('Defensive Summary'!C$1,Output!$A$3:$A$17,0),MATCH('Defensive Summary'!$A10,Output!$B$2:$P$2,0))*INDEX(Output!$B$3:$P$17,MATCH('Defensive Summary'!C$1,Output!$A$3:$A$17,0),MATCH('Defensive Summary'!$B10,Output!$B$2:$P$2,0)) -> 0.5 | D10: =INDEX(Output!$B$3:$P$17,MATCH('Defensive Summary'!D$1,Output!$A$3:$A$17,0),MATCH('Defensive Summary'!$A10,Output!$B$2:$P$2,0))*INDEX(Output!$B$3:$P$17,MATCH('Defensive Summary'!D$1,Output!$A$3:$A$17,0),MATCH('Defensive Summary'!$B10,Output!$B$2:$P$2,0)) -> 2 | E10: =INDEX(Output!$B$3:$P$17,MATCH('Defensive Summary'!E$1,Output!$A$3:$A$17,0),MATCH('Defensive Summary'!$A10,Output!$B$2:$P$2,0))*INDEX(Output!$B$3:$P$17,MATCH('Defensive Summary'!E$1,Output!$A$3:$A$17,0),MATCH('Defensive Summary'!$B10,Output!$B$2:$P$2,0)) -> 0.5 | F10: =INDEX(Output!$B$3:$P$17,MATCH('Defensive Summary'!F$1,Output!$A$3:$A$17,0),MATCH('Defensive Summary'!$A10,Output!$B$2:$P$2,0))*INDEX(Output!$B$3:$P$17,MATCH('Defensive Summary'!F$1,Output!$A$3:$A$17,0),MATCH('Defensive Summary'!$B10,Output!$B$2:$P$2,0)) -> 2 | G10: =INDEX(Output!$B$3:$P$17,MATCH('Defensive Summary'!G$1,Output!$A$3:$A$17,0),MATCH('Defensive Summary'!$A10,Output!$B$2:$P$2,0))*INDEX(Output!$B$3:$P$17,MATCH('Defensive Summary'!G$1,Output!$A$3:$A$17,0),MATCH('Defensive Summary'!$B10,Output!$B$2:$P$2,0)) -> 2 | H10: =INDEX(Output!$B$3:$P$17,MATCH('Defensive Summary'!H$1,Output!$A$3:$A$17,0),MATCH('Defensive Summary'!$A10,Output!$B$2:$P$2,0))*INDEX(Output!$B$3:$P$17,MATCH('Defensive Summary'!H$1,Output!$A$3:$A$17,0),MATCH('Defensive Summary'!$B10,Output!$B$2:$P$2,0)) -> 1 | I10: =INDEX(Output!$B$3:$P$17,MATCH('Defensive Summary'!I$1,Output!$A$3:$A$17,0),MATCH('Defensive Summary'!$A10,Output!$B$2:$P$2,0))*INDEX(Output!$B$3:$P$17,MATCH('Defensive Summary'!I$1,Output!$A$3:$A$17,0),MATCH('Defensive Summary'!$B10,Output!$B$2:$P$2,0)) -> 0.5 | J10: =INDEX(Output!$B$3:$P$17,MATCH('Defensive Summary'!J$1,Output!$A$3:$A$17,0),MATCH('Defensive Summary'!$A10,Output!$B$2:$P$2,0))*INDEX(Output!$B$3:$P$17,MATCH('Defensive Summary'!J$1,Output!$A$3:$A$17,0),MATCH('Defensive Summary'!$B10,Output!$B$2:$P$2,0)) -> 1 | ... Q10: =INDEX(Output!$B$3:$P$17,MATCH('Defensive Summary'!Q$1,Output!$A$3:$A$17,0),MATCH('Defensive Summary'!$A10,Output!$B$2:$P$2,0))*INDEX(Output!$B$3:$P$17,MATCH('Defensive Summary'!Q$1,Output!$A$3:$A$17,0),MATCH('Defensive Summary'!$B10,Output!$B$2:$P$2,0)) -> 1 | S10: =SUM(V10:AJ10) -> 3 | T10: Inferno | U10: Cursed | V10: {=_xlfn.IFS(C10=1,0,C10=2,-1,C10=4,-2,C10=0.5,1,C10=0.25,2,C10=0,4)} -> 1 | W10: {=_xlfn.IFS(D10=1,0,D10=2,-1,D10=4,-2,D10=0.5,1,D10=0.25,2,D10=0,4)} -> -1 | X10: {=_xlfn.IFS(E10=1,0,E10=2,-1,E10=4,-2,E10=0.5,1,E10=0.25,2,E10=0,4)} -> 1 | Y10: {=_xlfn.IFS(F10=1,0,F10=2,-1,F10=4,-2,F10=0.5,1,F10=0.25,2,F10=0,4)} -> -1 | Z10: {=_xlfn.IFS(G10=1,0,G10=2,-1,G10=4,-2,G10=0.5,1,G10=0.25,2,G10=0,4)} -> -1 | AA10: {=_xlfn.IFS(H10=1,0,H10=2,-1,H10=4,-2,H10=0.5,1,H10=0.25,2,H10=0,4)} -> 0 | AB10: {=_xlfn.IFS(I10=1,0,I10=2,-1,I10=4,-2,I10=0.5,1,I10=0.25,2,I10=0,4)} -> 1 | AC10: {=_xlfn.IFS(J10=1,0,J10=2,-1,J10=4,-2,J10=0.5,1,J10=0.25,2,J10=0,4)} -> 0 | ... AJ10: {=_xlfn.IFS(Q10=1,0,Q10=2,-1,Q10=4,-2,Q10=0.5,1,Q10=0.25,2,Q10=0,4)} -> 0
A11: Inferno | B11: Bless | C11: =INDEX(Output!$B$3:$P$17,MATCH('Defensive Summary'!C$1,Output!$A$3:$A$17,0),MATCH('Defensive Summary'!$A11,Output!$B$2:$P$2,0))*INDEX(Output!$B$3:$P$17,MATCH('Defensive Summary'!C$1,Output!$A$3:$A$17,0),MATCH('Defensive Summary'!$B11,Output!$B$2:$P$2,0)) -> 1 | D11: =INDEX(Output!$B$3:$P$17,MATCH('Defensive Summary'!D$1,Output!$A$3:$A$17,0),MATCH('Defensive Summary'!$A11,Output!$B$2:$P$2,0))*INDEX(Output!$B$3:$P$17,MATCH('Defensive Summary'!D$1,Output!$A$3:$A$17,0),MATCH('Defensive Summary'!$B11,Output!$B$2:$P$2,0)) -> 2 | E11: =INDEX(Output!$B$3:$P$17,MATCH('Defensive Summary'!E$1,Output!$A$3:$A$17,0),MATCH('Defensive Summary'!$A11,Output!$B$2:$P$2,0))*INDEX(Output!$B$3:$P$17,MATCH('Defensive Summary'!E$1,Output!$A$3:$A$17,0),MATCH('Defensive Summary'!$B11,Output!$B$2:$P$2,0)) -> 0.25 | F11: =INDEX(Output!$B$3:$P$17,MATCH('Defensive Summary'!F$1,Output!$A$3:$A$17,0),MATCH('Defensive Summary'!$A11,Output!$B$2:$P$2,0))*INDEX(Output!$B$3:$P$17,MATCH('Defensive Summary'!F$1,Output!$A$3:$A$17,0),MATCH('Defensive Summary'!$B11,Output!$B$2:$P$2,0)) -> 2 | G11: =INDEX(Output!$B$3:$P$17,MATCH('Defensive Summary'!G$1,Output!$A$3:$A$17,0),MATCH('Defensive Summary'!$A11,Output!$B$2:$P$2,0))*INDEX(Output!$B$3:$P$17,MATCH('Defensive Summary'!G$1,Output!$A$3:$A$17,0),MATCH('Defensive Summary'!$B11,Output!$B$2:$P$2,0)) -> 4 | H11: =INDEX(Output!$B$3:$P$17,MATCH('Defensive Summary'!H$1,Output!$A$3:$A$17,0),MATCH('Defensive Summary'!$A11,Output!$B$2:$P$2,0))*INDEX(Output!$B$3:$P$17,MATCH('Defensive Summary'!H$1,Output!$A$3:$A$17,0),MATCH('Defensive Summary'!$B11,Output!$B$2:$P$2,0)) -> 2 | I11: =INDEX(Output!$B$3:$P$17,MATCH('Defensive Summary'!I$1,Output!$A$3:$A$17,0),MATCH('Defensive Summary'!$A11,Output!$B$2:$P$2,0))*INDEX(Output!$B$3:$P$17,MATCH('Defensive Summary'!I$1,Output!$A$3:$A$17,0),MATCH('Defensive Summary'!$B11,Output!$B$2:$P$2,0)) -> 0.25 | J11: =INDEX(Output!$B$3:$P$17,MATCH('Defensive Summary'!J$1,Output!$A$3:$A$17,0),MATCH('Defensive Summary'!$A11,Output!$B$2:$P$2,0))*INDEX(Output!$B$3:$P$17,MATCH('Defensive Summary'!J$1,Output!$A$3:$A$17,0),MATCH('Defensive Summary'!$B11,Output!$B$2:$P$2,0)) -> 4 | ... Q11: =INDEX(Output!$B$3:$P$17,MATCH('Defensive Summary'!Q$1,Output!$A$3:$A$17,0),MATCH('Defensive Summary'!$A11,Output!$B$2:$P$2,0))*INDEX(Output!$B$3:$P$17,MATCH('Defensive Summary'!Q$1,Output!$A$3:$A$17,0),MATCH('Defensive Summary'!$B11,Output!$B$2:$P$2,0)) -> 1 | S11: =SUM(V11:AJ11) -> 3 | T11: Inferno | U11: Bless | V11: {=_xlfn.IFS(C11=1,0,C11=2,-1,C11=4,-2,C11=0.5,1,C11=0.25,2,C11=0,4)} -> 0 | W11: {=_xlfn.IFS(D11=1,0,D11=2,-1,D11=4,-2,D11=0.5,1,D11=0.25,2,D11=0,4)} -> -1 | X11: {=_xlfn.IFS(E11=1,0,E11=2,-1,E11=4,-2,E11=0.5,1,E11=0.25,2,E11=0,4)} -> 2 | Y11: {=_xlfn.IFS(F11=1,0,F11=2,-1,F11=4,-2,F11=0.5,1,F11=0.25,2,F11=0,4)} -> -1 | Z11: {=_xlfn.IFS(G11=1,0,G11=2,-1,G11=4,-2,G11=0.5,1,G11=0.25,2,G11=0,4)} -> -2 | AA11: {=_xlfn.IFS(H11=1,0,H11=2,-1,H11=4,-2,H11=0.5,1,H11=0.25,2,H11=0,4)} -> -1 | AB11: {=_xlfn.IFS(I11=1,0,I11=2,-1,I11=4,-2,I11=0.5,1,I11=0.25,2,I11=0,4)} -> 2 | AC11: {=_xlfn.IFS(J11=1,0,J11=2,-1,J11=4,-2,J11=0.5,1,J11=0.25,2,J11=0,4)} -> -2 | ... AJ11: {=_xlfn.IFS(Q11=1,0,Q11=2,-1,Q11=4,-2,Q11=0.5,1,Q11=0.25,2,Q11=0,4)} -> 0
A12: Inferno | B12: Mythos | C12: =INDEX(Output!$B$3:$P$17,MATCH('Defensive Summary'!C$1,Output!$A$3:$A$17,0),MATCH('Defensive Summary'!$A12,Output!$B$2:$P$2,0))*INDEX(Output!$B$3:$P$17,MATCH('Defensive Summary'!C$1,Output!$A$3:$A$17,0),MATCH('Defensive Summary'!$B12,Output!$B$2:$P$2,0)) -> 0.5 | D12: =INDEX(Output!$B$3:$P$17,MATCH('Defensive Summary'!D$1,Output!$A$3:$A$17,0),MATCH('Defensive Summary'!$A12,Output!$B$2:$P$2,0))*INDEX(Output!$B$3:$P$17,MATCH('Defensive Summary'!D$1,Output!$A$3:$A$17,0),MATCH('Defensive Summary'!$B12,Output!$B$2:$P$2,0)) -> 2 | E12: =INDEX(Output!$B$3:$P$17,MATCH('Defensive Summary'!E$1,Output!$A$3:$A$17,0),MATCH('Defensive Summary'!$A12,Output!$B$2:$P$2,0))*INDEX(Output!$B$3:$P$17,MATCH('Defensive Summary'!E$1,Output!$A$3:$A$17,0),MATCH('Defensive Summary'!$B12,Output!$B$2:$P$2,0)) -> 0.5 | F12: =INDEX(Output!$B$3:$P$17,MATCH('Defensive Summary'!F$1,Output!$A$3:$A$17,0),MATCH('Defensive Summary'!$A12,Output!$B$2:$P$2,0))*INDEX(Output!$B$3:$P$17,MATCH('Defensive Summary'!F$1,Output!$A$3:$A$17,0),MATCH('Defensive Summary'!$B12,Output!$B$2:$P$2,0)) -> 2 | G12: =INDEX(Output!$B$3:$P$17,MATCH('Defensive Summary'!G$1,Output!$A$3:$A$17,0),MATCH('Defensive Summary'!$A12,Output!$B$2:$P$2,0))*INDEX(Output!$B$3:$P$17,MATCH('Defensive Summary'!G$1,Output!$A$3:$A$17,0),MATCH('Defensive Summary'!$B12,Output!$B$2:$P$2,0)) -> 2 | H12: =INDEX(Output!$B$3:$P$17,MATCH('Defensive Summary'!H$1,Output!$A$3:$A$17,0),MATCH('Defensive Summary'!$A12,Output!$B$2:$P$2,0))*INDEX(Output!$B$3:$P$17,MATCH('Defensive Summary'!H$1,Output!$A$3:$A$17,0),MATCH('Defensive Summary'!$B12,Output!$B$2:$P$2,0)) -> 1 | I12: =INDEX(Output!$B$3:$P$17,MATCH('Defensive Summary'!I$1,Output!$A$3:$A$17,0),MATCH('Defensive Summary'!$A12,Output!$B$2:$P$2,0))*INDEX(Output!$B$3:$P$17,MATCH('Defensive Summary'!I$1,Output!$A$3:$A$17,0),MATCH('Defensive Summary'!$B12,Output!$B$2:$P$2,0)) -> 0.25 | J12: =INDEX(Output!$B$3:$P$17,MATCH('Defensive Summary'!J$1,Output!$A$3:$A$17,0),MATCH('Defensive Summary'!$A12,Output!$B$2:$P$2,0))*INDEX(Output!$B$3:$P$17,MATCH('Defensive Summary'!J$1,Output!$A$3:$A$17,0),MATCH('Defensive Summary'!$B12,Output!$B$2:$P$2,0)) -> 2 | ... Q12: =INDEX(Output!$B$3:$P$17,MATCH('Defensive Summary'!Q$1,Output!$A$3:$A$17,0),MATCH('Defensive Summary'!$A12,Output!$B$2:$P$2,0))*INDEX(Output!$B$3:$P$17,MATCH('Defensive Summary'!Q$1,Output!$A$3:$A$17,0),MATCH('Defensive Summary'!$B12,Output!$B$2:$P$2,0)) -> 1 | S12: =SUM(V12:AJ12) -> 1 | T12: Inferno | U12: Mythos | V12: {=_xlfn.IFS(C12=1,0,C12=2,-1,C12=4,-2,C12=0.5,1,C12=0.25,2,C12=0,4)} -> 1 | W12: {=_xlfn.IFS(D12=1,0,D12=2,-1,D12=4,-2,D12=0.5,1,D12=0.25,2,D12=0,4)} -> -1 | X12: {=_xlfn.IFS(E12=1,0,E12=2,-1,E12=4,-2,E12=0.5,1,E12=0.25,2,E12=0,4)} -> 1 | Y12: {=_xlfn.IFS(F12=1,0,F12=2,-1,F12=4,-2,F12=0.5,1,F12=0.25,2,F12=0,4)} -> -1 | Z12: {=_xlfn.IFS(G12=1,0,G12=2,-1,G12=4,-2,G12=0.5,1,G12=0.25,2,G12=0,4)} -> -1 | AA12: {=_xlfn.IFS(H12=1,0,H12=2,-1,H12=4,-2,H12=0.5,1,H12=0.25,2,H12=0,4)} -> 0 | AB12: {=_xlfn.IFS(I12=1,0,I12=2,-1,I12=4,-2,I12=0.5,1,I12=0.25,2,I12=0,4)} -> 2 | AC12: {=_xlfn.IFS(J12=1,0,J12=2,-1,J12=4,-2,J12=0.5,1,J12=0.25,2,J12=0,4)} -> -1 | ... AJ12: {=_xlfn.IFS(Q12=1,0,Q12=2,-1,Q12=4,-2,Q12=0.5,1,Q12=0.25,2,Q12=0,4)} -> 0
A13: Inferno | B13: Cyber | C13: =INDEX(Output!$B$3:$P$17,MATCH('Defensive Summary'!C$1,Output!$A$3:$A$17,0),MATCH('Defensive Summary'!$A13,Output!$B$2:$P$2,0))*INDEX(Output!$B$3:$P$17,MATCH('Defensive Summary'!C$1,Output!$A$3:$A$17,0),MATCH('Defensive Summary'!$B13,Output!$B$2:$P$2,0)) -> 1 | D13: =INDEX(Output!$B$3:$P$17,MATCH('Defensive Summary'!D$1,Output!$A$3:$A$17,0),MATCH('Defensive Summary'!$A13,Output!$B$2:$P$2,0))*INDEX(Output!$B$3:$P$17,MATCH('Defensive Summary'!D$1,Output!$A$3:$A$17,0),MATCH('Defensive Summary'!$B13,Output!$B$2:$P$2,0)) -> 4 | E13: =INDEX(Output!$B$3:$P$17,MATCH('Defensive Summary'!E$1,Output!$A$3:$A$17,0),MATCH('Defensive Summary'!$A13,Output!$B$2:$P$2,0))*INDEX(Output!$B$3:$P$17,MATCH('Defensive Summary'!E$1,Output!$A$3:$A$17,0),MATCH('Defensive Summary'!$B13,Output!$B$2:$P$2,0)) -> 1 | F13: =INDEX(Output!$B$3:$P$17,MATCH('Defensive Summary'!F$1,Output!$A$3:$A$17,0),MATCH('Defensive Summary'!$A13,Output!$B$2:$P$2,0))*INDEX(Output!$B$3:$P$17,MATCH('Defensive Summary'!F$1,Output!$A$3:$A$17,0),MATCH('Defensive Summary'!$B13,Output!$B$2:$P$2,0)) -> 2 | G13: =INDEX(Output!$B$3:$P$17,MATCH('Defensive Summary'!G$1,Output!$A$3:$A$17,0),MATCH('Defensive Summary'!$A13,Output!$B$2:$P$2,0))*INDEX(Output!$B$3:$P$17,MATCH('Defensive Summary'!G$1,Output!$A$3:$A$17,0),MATCH('Defensive Summary'!$B13,Output!$B$2:$P$2,0)) -> 1 | H13: =INDEX(Output!$B$3:$P$17,MATCH('Defensive Summary'!H$1,Output!$A$3:$A$17,0),MATCH('Defensive Summary'!$A13,Output!$B$2:$P$2,0))*INDEX(Output!$B$3:$P$17,MATCH('Defensive Summary'!H$1,Output!$A$3:$A$17,0),MATCH('Defensive Summary'!$B13,Output!$B$2:$P$2,0)) -> 2 | I13: =INDEX(Output!$B$3:$P$17,MATCH('Defensive Summary'!I$1,Output!$A$3:$A$17,0),MATCH('Defensive Summary'!$A13,Output!$B$2:$P$2,0))*INDEX(Output!$B$3:$P$17,MATCH('Defensive Summary'!I$1,Output!$A$3:$A$17,0),MATCH('Defensive Summary'!$B13,Output!$B$2:$P$2,0)) -> 1 | J13: =INDEX(Output!$B$3:$P$17,MATCH('Defensive Summary'!J$1,Output!$A$3:$A$17,0),MATCH('Defensive Summary'!$A13,Output!$B$2:$P$2,0))*INDEX(Output!$B$3:$P$17,MATCH('Defensive Summary'!J$1,Output!$A$3:$A$17,0),MATCH('Defensive Summary'!$B13,Output!$B$2:$P$2,0)) -> 1 | ... Q13: =INDEX(Output!$B$3:$P$17,MATCH('Defensive Summary'!Q$1,Output!$A$3:$A$17,0),MATCH('Defensive Summary'!$A13,Output!$B$2:$P$2,0))*INDEX(Output!$B$3:$P$17,MATCH('Defensive Summary'!Q$1,Output!$A$3:$A$17,0),MATCH('Defensive Summary'!$B13,Output!$B$2:$P$2,0)) -> 1 | S13: =SUM(V13:AJ13) -> 4 | T13: Inferno | U13: Cyber | V13: {=_xlfn.IFS(C13=1,0,C13=2,-1,C13=4,-2,C13=0.5,1,C13=0.25,2,C13=0,4)} -> 0 | W13: {=_xlfn.IFS(D13=1,0,D13=2,-1,D13=4,-2,D13=0.5,1,D13=0.25,2,D13=0,4)} -> -2 | X13: {=_xlfn.IFS(E13=1,0,E13=2,-1,E13=4,-2,E13=0.5,1,E13=0.25,2,E13=0,4)} -> 0 | Y13: {=_xlfn.IFS(F13=1,0,F13=2,-1,F13=4,-2,F13=0.5,1,F13=0.25,2,F13=0,4)} -> -1 | Z13: {=_xlfn.IFS(G13=1,0,G13=2,-1,G13=4,-2,G13=0.5,1,G13=0.25,2,G13=0,4)} -> 0 | AA13: {=_xlfn.IFS(H13=1,0,H13=2,-1,H13=4,-2,H13=0.5,1,H13=0.25,2,H13=0,4)} -> -1 | AB13: {=_xlfn.IFS(I13=1,0,I13=2,-1,I13=4,-2,I13=0.5,1,I13=0.25,2,I13=0,4)} -> 0 | AC13: {=_xlfn.IFS(J13=1,0,J13=2,-1,J13=4,-2,J13=0.5,1,J13=0.25,2,J13=0,4)} -> 0 | ... AJ13: {=_xlfn.IFS(Q13=1,0,Q13=2,-1,Q13=4,-2,Q13=0.5,1,Q13=0.25,2,Q13=0,4)} -> 0
... A106: Cosmic | B106: Neutral | C106: =INDEX(Output!$B$3:$P$17,MATCH('Defensive Summary'!C$1,Output!$A$3:$A$17,0),MATCH('Defensive Summary'!$A106,Output!$B$2:$P$2,0))*INDEX(Output!$B$3:$P$17,MATCH('Defensive Summary'!C$1,Output!$A$3:$A$17,0),MATCH('Defensive Summary'!$B106,Output!$B$2:$P$2,0)) -> 1 | D106: =INDEX(Output!$B$3:$P$17,MATCH('Defensive Summary'!D$1,Output!$A$3:$A$17,0),MATCH('Defensive Summary'!$A106,Output!$B$2:$P$2,0))*INDEX(Output!$B$3:$P$17,MATCH('Defensive Summary'!D$1,Output!$A$3:$A$17,0),MATCH('Defensive Summary'!$B106,Output!$B$2:$P$2,0)) -> 0.5 | E106: =INDEX(Output!$B$3:$P$17,MATCH('Defensive Summary'!E$1,Output!$A$3:$A$17,0),MATCH('Defensive Summary'!$A106,Output!$B$2:$P$2,0))*INDEX(Output!$B$3:$P$17,MATCH('Defensive Summary'!E$1,Output!$A$3:$A$17,0),MATCH('Defensive Summary'!$B106,Output!$B$2:$P$2,0)) -> 1 | F106: =INDEX(Output!$B$3:$P$17,MATCH('Defensive Summary'!F$1,Output!$A$3:$A$17,0),MATCH('Defensive Summary'!$A106,Output!$B$2:$P$2,0))*INDEX(Output!$B$3:$P$17,MATCH('Defensive Summary'!F$1,Output!$A$3:$A$17,0),MATCH('Defensive Summary'!$B106,Output!$B$2:$P$2,0)) -> 1 | G106: =INDEX(Output!$B$3:$P$17,MATCH('Defensive Summary'!G$1,Output!$A$3:$A$17,0),MATCH('Defensive Summary'!$A106,Output!$B$2:$P$2,0))*INDEX(Output!$B$3:$P$17,MATCH('Defensive Summary'!G$1,Output!$A$3:$A$17,0),MATCH('Defensive Summary'!$B106,Output!$B$2:$P$2,0)) -> 1 | H106: =INDEX(Output!$B$3:$P$17,MATCH('Defensive Summary'!H$1,Output!$A$3:$A$17,0),MATCH('Defensive Summary'!$A106,Output!$B$2:$P$2,0))*INDEX(Output!$B$3:$P$17,MATCH('Defensive Summary'!H$1,Output!$A$3:$A$17,0),MATCH('Defensive Summary'!$B106,Output!$B$2:$P$2,0)) -> 0.5 | I106: =INDEX(Output!$B$3:$P$17,MATCH('Defensive Summary'!I$1,Output!$A$3:$A$17,0),MATCH('Defensive Summary'!$A106,Output!$B$2:$P$2,0))*INDEX(Output!$B$3:$P$17,MATCH('Defensive Summary'!I$1,Output!$A$3:$A$17,0),MATCH('Defensive Summary'!$B106,Output!$B$2:$P$2,0)) -> 0.5 | J106: =INDEX(Output!$B$3:$P$17,MATCH('Defensive Summary'!J$1,Output!$A$3:$A$17,0),MATCH('Defensive Summary'!$A106,Output!$B$2:$P$2,0))*INDEX(Output!$B$3:$P$17,MATCH('Defensive Summary'!J$1,Output!$A$3:$A$17,0),MATCH('Defensive Summary'!$B106,Output!$B$2:$P$2,0)) -> 1 | ... Q106: =INDEX(Output!$B$3:$P$17,MATCH('Defensive Summary'!Q$1,Output!$A$3:$A$17,0),MATCH('Defensive Summary'!$A106,Output!$B$2:$P$2,0))*INDEX(Output!$B$3:$P$17,MATCH('Defensive Summary'!Q$1,Output!$A$3:$A$17,0),MATCH('Defensive Summary'!$B106,Output!$B$2:$P$2,0)) -> 1 | S106: =SUM(V106:AJ106) -> 4 | T106: Cosmic | U106: Neutral | V106: {=_xlfn.IFS(C106=1,0,C106=2,-1,C106=4,-2,C106=0.5,1,C106=0.25,2,C106=0,4)} -> 0 | W106: {=_xlfn.IFS(D106=1,0,D106=2,-1,D106=4,-2,D106=0.5,1,D106=0.25,2,D106=0,4)} -> 1 | X106: {=_xlfn.IFS(E106=1,0,E106=2,-1,E106=4,-2,E106=0.5,1,E106=0.25,2,E106=0,4)} -> 0 | Y106: {=_xlfn.IFS(F106=1,0,F106=2,-1,F106=4,-2,F106=0.5,1,F106=0.25,2,F106=0,4)} -> 0 | Z106: {=_xlfn.IFS(G106=1,0,G106=2,-1,G106=4,-2,G106=0.5,1,G106=0.25,2,G106=0,4)} -> 0 | AA106: {=_xlfn.IFS(H106=1,0,H106=2,-1,H106=4,-2,H106=0.5,1,H106=0.25,2,H106=0,4)} -> 1 | AB106: {=_xlfn.IFS(I106=1,0,I106=2,-1,I106=4,-2,I106=0.5,1,I106=0.25,2,I106=0,4)} -> 1 | AC106: {=_xlfn.IFS(J106=1,0,J106=2,-1,J106=4,-2,J106=0.5,1,J106=0.25,2,J106=0,4)} -> 0 | ... AJ106: {=_xlfn.IFS(Q106=1,0,Q106=2,-1,Q106=4,-2,Q106=0.5,1,Q106=0.25,2,Q106=0,4)} -> 0
